[update.log]


Thu Jan 18 22:46:01 JST 2024
Thu Jan 18 22:47:00 JST 2024
Thu Jan 18 22:48:00 JST 2024
update schedule complete
update champion complete
update ranking_24_spring complete
-------------------------------------
update schedule complete
update champion complete
update ranking_24_spring complete
-------------------------------------
Thu Jan 18 22:49:00 JST 2024
update schedule complete
update champion complete
update ranking_24_spring complete
-------------------------------------
Thu Jan 18 22:50:00 JST 2024
update schedule complete
Traceback (most recent call last):
  File "/Users/kimminseok/Library/Mobile Documents/com~apple~CloudDocs/Desktop/coding/LCKlol/manage.py", line 22, in <module>
    main()
  File "/Users/kimminseok/Library/Mobile Documents/com~apple~CloudDocs/Desktop/coding/LCKlol/manage.py", line 18, in main
    execute_from_command_line(sys.argv)
  File "/Library/Frameworks/Python.framework/Versions/3.10/lib/python3.10/site-packages/django/core/management/__init__.py", line 446, in execute_from_command_line
    utility.execute()
  File "/Library/Frameworks/Python.framework/Versions/3.10/lib/python3.10/site-packages/django/core/management/__init__.py", line 440, in execute
    self.fetch_command(subcommand).run_from_argv(self.argv)
  File "/Library/Frameworks/Python.framework/Versions/3.10/lib/python3.10/site-packages/django/core/management/base.py", line 414, in run_from_argv
    self.execute(*args, **cmd_options)
  File "/Library/Frameworks/Python.framework/Versions/3.10/lib/python3.10/site-packages/django/core/management/base.py", line 460, in execute
    output = self.handle(*args, **options)
  File "/Users/kimminseok/Library/Mobile Documents/com~apple~CloudDocs/Desktop/coding/LCKlol/index/management/commands/update.py", line 525, in handle
    self.update_champion()
  File "/Users/kimminseok/Library/Mobile Documents/com~apple~CloudDocs/Desktop/coding/LCKlol/index/management/commands/update.py", line 361, in update_champion
    driver.get(URL)
  File "/Library/Frameworks/Python.framework/Versions/3.10/lib/python3.10/site-packages/selenium/webdriver/remote/webdriver.py", line 353, in get
    self.execute(Command.GET, {"url": url})
  File "/Library/Frameworks/Python.framework/Versions/3.10/lib/python3.10/site-packages/selenium/webdriver/remote/webdriver.py", line 344, in execute
    self.error_handler.check_response(response)
  File "/Library/Frameworks/Python.framework/Versions/3.10/lib/python3.10/site-packages/selenium/webdriver/remote/errorhandler.py", line 229, in check_response
    raise exception_class(message, screen, stacktrace)
selenium.common.exceptions.WebDriverException: Message: disconnected: Unable to receive message from renderer
  (failed to check if window was closed: disconnected: not connected to DevTools)
  (Session info: chrome-headless-shell=120.0.6099.216)
Stacktrace:
0   chromedriver                        0x0000000100b444dc chromedriver + 4162780
1   chromedriver                        0x0000000100b3c664 chromedriver + 4130404
2   chromedriver                        0x0000000100793bc0 chromedriver + 293824
3   chromedriver                        0x000000010077bc3c chromedriver + 195644
4   chromedriver                        0x000000010077bad0 chromedriver + 195280
5   chromedriver                        0x000000010077b254 chromedriver + 193108
6   chromedriver                        0x000000010079f19c chromedriver + 340380
7   chromedriver                        0x0000000100819bd8 chromedriver + 842712
8   chromedriver                        0x00000001007cd6bc chromedriver + 530108
9   chromedriver                        0x00000001007ce930 chromedriver + 534832
10  chromedriver                        0x0000000100b09e08 chromedriver + 3923464
11  chromedriver                        0x0000000100b0e3dc chromedriver + 3941340
12  chromedriver                        0x0000000100af2038 chromedriver + 3825720
13  chromedriver                        0x0000000100b0ef3c chromedriver + 3944252
14  chromedriver                        0x0000000100ae46f4 chromedriver + 3770100
15  chromedriver                        0x0000000100b2b980 chromedriver + 4061568
16  chromedriver                        0x0000000100b2baf8 chromedriver + 4061944
17  chromedriver                        0x0000000100b3c2e4 chromedriver + 4129508
18  libsystem_pthread.dylib             0x0000000183ba2034 _pthread_start + 136
19  libsystem_pthread.dylib             0x0000000183b9ce3c thread_start + 8

update schedule complete
Traceback (most recent call last):
  File "/Users/kimminseok/Library/Mobile Documents/com~apple~CloudDocs/Desktop/coding/LCKlol/manage.py", line 22, in <module>
    main()
  File "/Users/kimminseok/Library/Mobile Documents/com~apple~CloudDocs/Desktop/coding/LCKlol/manage.py", line 18, in main
    execute_from_command_line(sys.argv)
  File "/Library/Frameworks/Python.framework/Versions/3.10/lib/python3.10/site-packages/django/core/management/__init__.py", line 446, in execute_from_command_line
    utility.execute()
  File "/Library/Frameworks/Python.framework/Versions/3.10/lib/python3.10/site-packages/django/core/management/__init__.py", line 440, in execute
    self.fetch_command(subcommand).run_from_argv(self.argv)
  File "/Library/Frameworks/Python.framework/Versions/3.10/lib/python3.10/site-packages/django/core/management/base.py", line 414, in run_from_argv
    self.execute(*args, **cmd_options)
  File "/Library/Frameworks/Python.framework/Versions/3.10/lib/python3.10/site-packages/django/core/management/base.py", line 460, in execute
    output = self.handle(*args, **options)
  File "/Users/kimminseok/Library/Mobile Documents/com~apple~CloudDocs/Desktop/coding/LCKlol/index/management/commands/update.py", line 525, in handle
    self.update_champion()
  File "/Users/kimminseok/Library/Mobile Documents/com~apple~CloudDocs/Desktop/coding/LCKlol/index/management/commands/update.py", line 365, in update_champion
    web_source = driver.page_source
  File "/Library/Frameworks/Python.framework/Versions/3.10/lib/python3.10/site-packages/selenium/webdriver/remote/webdriver.py", line 445, in page_source
    return self.execute(Command.GET_PAGE_SOURCE)["value"]
  File "/Library/Frameworks/Python.framework/Versions/3.10/lib/python3.10/site-packages/selenium/webdriver/remote/webdriver.py", line 344, in execute
    self.error_handler.check_response(response)
  File "/Library/Frameworks/Python.framework/Versions/3.10/lib/python3.10/site-packages/selenium/webdriver/remote/errorhandler.py", line 229, in check_response
    raise exception_class(message, screen, stacktrace)
selenium.common.exceptions.WebDriverException: Message: disconnected: not connected to DevTools
  (failed to check if window was closed: disconnected: not connected to DevTools)
  (Session info: chrome-headless-shell=120.0.6099.216)
Stacktrace:
0   chromedriver                        0x0000000102a344dc chromedriver + 4162780
1   chromedriver                        0x0000000102a2c664 chromedriver + 4130404
2   chromedriver                        0x0000000102683bc0 chromedriver + 293824
3   chromedriver                        0x000000010266b0b0 chromedriver + 192688
4   chromedriver                        0x000000010266afd8 chromedriver + 192472
5   chromedriver                        0x00000001027092b0 chromedriver + 840368
6   chromedriver                        0x00000001026bd6bc chromedriver + 530108
7   chromedriver                        0x00000001026be930 chromedriver + 534832
8   chromedriver                        0x00000001029f9e08 chromedriver + 3923464
9   chromedriver                        0x00000001029fe3dc chromedriver + 3941340
10  chromedriver                        0x00000001029e2038 chromedriver + 3825720
11  chromedriver                        0x00000001029fef3c chromedriver + 3944252
12  chromedriver                        0x00000001029d46f4 chromedriver + 3770100
13  chromedriver                        0x0000000102a1b980 chromedriver + 4061568
14  chromedriver                        0x0000000102a1baf8 chromedriver + 4061944
15  chromedriver                        0x0000000102a2c2e4 chromedriver + 4129508
16  libsystem_pthread.dylib             0x0000000183ba2034 _pthread_start + 136
17  libsystem_pthread.dylib             0x0000000183b9ce3c thread_start + 8

-------------------------------------
-------------------------------------
Thu Jan 18 22:51:02 JST 2024
Thu Jan 18 22:53:30 JST 2024
Thu Jan 18 22:59:47 JST 2024
Thu Jan 18 23:00:00 JST 2024
Thu Jan 18 23:01:01 JST 2024
update schedule complete
update champion complete
update ranking_24_spring complete
-------------------------------------
update schedule complete
update champion complete
update ranking_24_spring complete
-------------------------------------
update schedule complete
update champion complete
update ranking_24_spring complete
-------------------------------------
Thu Jan 18 23:34:00 JST 2024
update schedule complete
update champion complete
update ranking_24_spring complete
-------------------------------------
update schedule complete
update champion complete
update ranking_24_spring complete
-------------------------------------
Thu Jan 18 23:52:00 JST 2024
update schedule complete
update champion complete
update ranking_24_spring complete
-------------------------------------
Thu Jan 18 23:53:00 JST 2024
update schedule complete
update champion complete
update ranking_24_spring complete
-------------------------------------
Thu Jan 18 23:54:00 JST 2024
update schedule complete
update champion complete
update ranking_24_spring complete
-------------------------------------
Thu Jan 18 23:55:00 JST 2024
update schedule complete
update champion complete
update ranking_24_spring complete
-------------------------------------
Fri Jan 19 00:13:00 JST 2024
Fri Jan 19 00:14:00 JST 2024
update schedule complete
update champion complete
update ranking_24_spring complete
-------------------------------------
update schedule complete
update champion complete
update ranking_24_spring complete
-------------------------------------
Fri Jan 19 00:30:00 JST 2024
update schedule complete
update champion complete
update ranking_24_spring complete
-------------------------------------
Fri Jan 19 00:31:00 JST 2024
Fri Jan 19 00:32:00 JST 2024
update schedule complete
update champion complete
update ranking_24_spring complete
-------------------------------------
Fri Jan 19 00:33:00 JST 2024
update schedule complete
update champion complete
update ranking_24_spring complete
-------------------------------------
Fri Jan 19 00:50:01 JST 2024
update schedule complete
update champion complete
update ranking_24_spring complete
-------------------------------------
update schedule complete
update champion complete
update ranking_24_spring complete
-------------------------------------
Fri Jan 19 01:08:00 JST 2024
Fri Jan 19 01:09:00 JST 2024
update schedule complete
update champion complete
update ranking_24_spring complete
-------------------------------------
Fri Jan 19 01:26:00 JST 2024
Fri Jan 19 01:27:00 JST 2024
Fri Jan 19 01:28:00 JST 2024
update schedule complete
update champion complete
update ranking_24_spring complete
-------------------------------------
update schedule complete
update champion complete
update ranking_24_spring complete
-------------------------------------
Fri Jan 19 01:46:01 JST 2024
update schedule complete
update champion complete
update ranking_24_spring complete
-------------------------------------
Fri Jan 19 01:47:00 JST 2024
update schedule complete
update champion complete
update ranking_24_spring complete
-------------------------------------
Fri Jan 19 01:48:00 JST 2024
update schedule complete
update champion complete
update ranking_24_spring complete
-------------------------------------
update schedule complete
update champion complete
update ranking_24_spring complete
-------------------------------------
Fri Jan 19 02:07:00 JST 2024
update schedule complete
update champion complete
update ranking_24_spring complete
-------------------------------------
Fri Jan 19 02:08:00 JST 2024
Fri Jan 19 02:26:00 JST 2024
update schedule complete
update champion complete
update ranking_24_spring complete
-------------------------------------
Fri Jan 19 02:27:01 JST 2024
Fri Jan 19 02:45:00 JST 2024
update schedule complete
update champion complete
update ranking_24_spring complete
-------------------------------------
Fri Jan 19 02:46:00 JST 2024
update schedule complete
update champion complete
update ranking_24_spring complete
-------------------------------------
Fri Jan 19 02:47:00 JST 2024
update schedule complete
update champion complete
update ranking_24_spring complete
-------------------------------------
update schedule complete
update champion complete
update ranking_24_spring complete
-------------------------------------
Fri Jan 19 02:48:00 JST 2024
Fri Jan 19 03:06:01 JST 2024
update schedule complete
update champion complete
update ranking_24_spring complete
-------------------------------------
update schedule complete
update champion complete
update ranking_24_spring complete
-------------------------------------
Fri Jan 19 03:07:00 JST 2024
Fri Jan 19 03:08:01 JST 2024
update schedule complete
update champion complete
update ranking_24_spring complete
-------------------------------------
Fri Jan 19 03:09:00 JST 2024
update schedule complete
update champion complete
update ranking_24_spring complete
-------------------------------------
Fri Jan 19 03:10:00 JST 2024
update schedule complete
update champion complete
update ranking_24_spring complete
-------------------------------------
Fri Jan 19 03:27:00 JST 2024
update schedule complete
update champion complete
update ranking_24_spring complete
-------------------------------------
Fri Jan 19 03:28:00 JST 2024
update schedule complete
update champion complete
update ranking_24_spring complete
-------------------------------------
Fri Jan 19 03:45:00 JST 2024
update schedule complete
update champion complete
update ranking_24_spring complete
-------------------------------------
Fri Jan 19 03:46:00 JST 2024
update schedule complete
update champion complete
update ranking_24_spring complete
-------------------------------------
update schedule complete
update champion complete
update ranking_24_spring complete
-------------------------------------
Fri Jan 19 04:03:00 JST 2024
update schedule complete
update champion complete
update ranking_24_spring complete
-------------------------------------
Fri Jan 19 04:04:00 JST 2024
Fri Jan 19 04:05:00 JST 2024
update schedule complete
update champion complete
update ranking_24_spring complete
-------------------------------------
Fri Jan 19 04:22:00 JST 2024
update schedule complete
update champion complete
update ranking_24_spring complete
-------------------------------------
Fri Jan 19 04:39:00 JST 2024
update schedule complete
update champion complete
update ranking_24_spring complete
-------------------------------------
Fri Jan 19 04:40:00 JST 2024
update schedule complete
update champion complete
update ranking_24_spring complete
-------------------------------------
update schedule complete
update champion complete
update ranking_24_spring complete
-------------------------------------
Fri Jan 19 04:41:00 JST 2024
Fri Jan 19 04:42:00 JST 2024
update schedule complete
update champion complete
update ranking_24_spring complete
-------------------------------------
update schedule complete
update champion complete
update ranking_24_spring complete
-------------------------------------
Fri Jan 19 04:43:00 JST 2024
Fri Jan 19 04:44:00 JST 2024
update schedule complete
update champion complete
update ranking_24_spring complete
-------------------------------------
Fri Jan 19 05:03:00 JST 2024
update schedule complete
update champion complete
update ranking_24_spring complete
-------------------------------------
Fri Jan 19 05:04:00 JST 2024
update schedule complete
update champion complete
update ranking_24_spring complete
-------------------------------------
Fri Jan 19 05:21:00 JST 2024
update schedule complete
update champion complete
update ranking_24_spring complete
-------------------------------------
Fri Jan 19 05:22:01 JST 2024
update schedule complete
update champion complete
update ranking_24_spring complete
-------------------------------------
update schedule complete
update champion complete
update ranking_24_spring complete
-------------------------------------
Fri Jan 19 05:23:00 JST 2024
update schedule complete
update champion complete
update ranking_24_spring complete
-------------------------------------
Fri Jan 19 05:24:00 JST 2024
update schedule complete
update champion complete
update ranking_24_spring complete
-------------------------------------
Fri Jan 19 05:25:00 JST 2024
update schedule complete
update champion complete
update ranking_24_spring complete
-------------------------------------
Fri Jan 19 05:26:00 JST 2024
update schedule complete
update champion complete
update ranking_24_spring complete
-------------------------------------
Fri Jan 19 05:27:00 JST 2024
Fri Jan 19 05:28:00 JST 2024
update schedule complete
update champion complete
update ranking_24_spring complete
-------------------------------------
Fri Jan 19 05:29:00 JST 2024
update schedule complete
update champion complete
update ranking_24_spring complete
-------------------------------------
update schedule complete
update champion complete
update ranking_24_spring complete
-------------------------------------
Fri Jan 19 05:30:00 JST 2024
Fri Jan 19 05:31:00 JST 2024
update schedule complete
update champion complete
update ranking_24_spring complete
-------------------------------------
Fri Jan 19 05:49:00 JST 2024
update schedule complete
update champion complete
update ranking_24_spring complete
-------------------------------------
Fri Jan 19 05:50:00 JST 2024
update schedule complete
update champion complete
update ranking_24_spring complete
-------------------------------------
Fri Jan 19 06:07:01 JST 2024
Fri Jan 19 06:08:00 JST 2024
update schedule complete
update champion complete
update ranking_24_spring complete
-------------------------------------
Fri Jan 19 06:25:00 JST 2024
update schedule complete
update champion complete
update ranking_24_spring complete
-------------------------------------
update schedule complete
update champion complete
update ranking_24_spring complete
-------------------------------------
Fri Jan 19 06:26:00 JST 2024
update schedule complete
update champion complete
update ranking_24_spring complete
-------------------------------------
update schedule complete
update champion complete
update ranking_24_spring complete
-------------------------------------
Fri Jan 19 06:27:00 JST 2024
Fri Jan 19 06:28:00 JST 2024
update schedule complete
update champion complete
update ranking_24_spring complete
-------------------------------------
update schedule complete
update champion complete
update ranking_24_spring complete
-------------------------------------
Fri Jan 19 06:29:00 JST 2024
update schedule complete
update champion complete
update ranking_24_spring complete
-------------------------------------
Fri Jan 19 06:30:00 JST 2024
update schedule complete
update champion complete
update ranking_24_spring complete
-------------------------------------
Fri Jan 19 06:31:00 JST 2024
update schedule complete
update champion complete
update ranking_24_spring complete
-------------------------------------
Fri Jan 19 06:32:00 JST 2024
update schedule complete
update champion complete
update ranking_24_spring complete
-------------------------------------
Fri Jan 19 06:33:00 JST 2024
update schedule complete
update champion complete
update ranking_24_spring complete
-------------------------------------
Fri Jan 19 06:34:40 JST 2024
Fri Jan 19 06:35:00 JST 2024
update schedule complete
update champion complete
update ranking_24_spring complete
-------------------------------------
Fri Jan 19 06:52:00 JST 2024
Fri Jan 19 07:09:00 JST 2024
update schedule complete
update champion complete
update ranking_24_spring complete
-------------------------------------
Fri Jan 19 07:10:01 JST 2024
update schedule complete
update champion complete
update ranking_24_spring complete
-------------------------------------
update schedule complete
update champion complete
update ranking_24_spring complete
-------------------------------------
Fri Jan 19 07:27:01 JST 2024
Fri Jan 19 07:28:00 JST 2024
Fri Jan 19 07:45:00 JST 2024
update schedule complete
update champion complete
update ranking_24_spring complete
-------------------------------------
update schedule complete
update champion complete
update ranking_24_spring complete
-------------------------------------
Fri Jan 19 07:46:00 JST 2024
update schedule complete
update champion complete
update ranking_24_spring complete
-------------------------------------
Fri Jan 19 07:47:00 JST 2024
update schedule complete
update champion complete
update ranking_24_spring complete
-------------------------------------
update schedule complete
update champion complete
update ranking_24_spring complete
-------------------------------------
Fri Jan 19 07:48:01 JST 2024
update schedule complete
update champion complete
Traceback (most recent call last):
  File "/Library/Frameworks/Python.framework/Versions/3.10/lib/python3.10/site-packages/django/db/backends/utils.py", line 89, in _execute
    return self.cursor.execute(sql, params)
  File "/Library/Frameworks/Python.framework/Versions/3.10/lib/python3.10/site-packages/django/db/backends/mysql/base.py", line 75, in execute
    return self.cursor.execute(query, args)
  File "/Library/Frameworks/Python.framework/Versions/3.10/lib/python3.10/site-packages/MySQLdb/cursors.py", line 179, in execute
    res = self._query(mogrified_query)
  File "/Library/Frameworks/Python.framework/Versions/3.10/lib/python3.10/site-packages/MySQLdb/cursors.py", line 330, in _query
    db.query(q)
  File "/Library/Frameworks/Python.framework/Versions/3.10/lib/python3.10/site-packages/MySQLdb/connections.py", line 255, in query
    _mysql.connection.query(self, query)
MySQLdb.OperationalError: (2013, 'Lost connection to MySQL server during query')

The above exception was the direct cause of the following exception:

Traceback (most recent call last):
  File "/Users/kimminseok/Library/Mobile Documents/com~apple~CloudDocs/Desktop/coding/LCKlol/manage.py", line 22, in <module>
    main()
  File "/Users/kimminseok/Library/Mobile Documents/com~apple~CloudDocs/Desktop/coding/LCKlol/manage.py", line 18, in main
    execute_from_command_line(sys.argv)
  File "/Library/Frameworks/Python.framework/Versions/3.10/lib/python3.10/site-packages/django/core/management/__init__.py", line 446, in execute_from_command_line
    utility.execute()
  File "/Library/Frameworks/Python.framework/Versions/3.10/lib/python3.10/site-packages/django/core/management/__init__.py", line 440, in execute
    self.fetch_command(subcommand).run_from_argv(self.argv)
  File "/Library/Frameworks/Python.framework/Versions/3.10/lib/python3.10/site-packages/django/core/management/base.py", line 414, in run_from_argv
    self.execute(*args, **cmd_options)
  File "/Library/Frameworks/Python.framework/Versions/3.10/lib/python3.10/site-packages/django/core/management/base.py", line 460, in execute
    output = self.handle(*args, **options)
  File "/Users/kimminseok/Library/Mobile Documents/com~apple~CloudDocs/Desktop/coding/LCKlol/index/management/commands/update.py", line 527, in handle
    self.update_ranking_24_spring_regular()
  File "/Users/kimminseok/Library/Mobile Documents/com~apple~CloudDocs/Desktop/coding/LCKlol/index/management/commands/update.py", line 492, in update_ranking_24_spring_regular
    self.reset_ranking_24_spring_regular()
  File "/Users/kimminseok/Library/Mobile Documents/com~apple~CloudDocs/Desktop/coding/LCKlol/index/management/commands/update.py", line 483, in reset_ranking_24_spring_regular
    team_object = Ranking_24_spring_regular.objects.get(tricode=team)
  File "/Library/Frameworks/Python.framework/Versions/3.10/lib/python3.10/site-packages/django/db/models/manager.py", line 85, in manager_method
    return getattr(self.get_queryset(), name)(*args, **kwargs)
  File "/Library/Frameworks/Python.framework/Versions/3.10/lib/python3.10/site-packages/django/db/models/query.py", line 492, in get
    num = len(clone)
  File "/Library/Frameworks/Python.framework/Versions/3.10/lib/python3.10/site-packages/django/db/models/query.py", line 302, in __len__
    self._fetch_all()
  File "/Library/Frameworks/Python.framework/Versions/3.10/lib/python3.10/site-packages/django/db/models/query.py", line 1507, in _fetch_all
    self._result_cache = list(self._iterable_class(self))
  File "/Library/Frameworks/Python.framework/Versions/3.10/lib/python3.10/site-packages/django/db/models/query.py", line 57, in __iter__
    results = compiler.execute_sql(
  File "/Library/Frameworks/Python.framework/Versions/3.10/lib/python3.10/site-packages/django/db/models/sql/compiler.py", line 1361, in execute_sql
    cursor.execute(sql, params)
  File "/Library/Frameworks/Python.framework/Versions/3.10/lib/python3.10/site-packages/django/db/backends/utils.py", line 103, in execute
    return super().execute(sql, params)
  File "/Library/Frameworks/Python.framework/Versions/3.10/lib/python3.10/site-packages/django/db/backends/utils.py", line 67, in execute
    return self._execute_with_wrappers(
  File "/Library/Frameworks/Python.framework/Versions/3.10/lib/python3.10/site-packages/django/db/backends/utils.py", line 80, in _execute_with_wrappers
    return executor(sql, params, many, context)
  File "/Library/Frameworks/Python.framework/Versions/3.10/lib/python3.10/site-packages/django/db/backends/utils.py", line 84, in _execute
    with self.db.wrap_database_errors:
  File "/Library/Frameworks/Python.framework/Versions/3.10/lib/python3.10/site-packages/django/db/utils.py", line 91, in __exit__
    raise dj_exc_value.with_traceback(traceback) from exc_value
  File "/Library/Frameworks/Python.framework/Versions/3.10/lib/python3.10/site-packages/django/db/backends/utils.py", line 89, in _execute
    return self.cursor.execute(sql, params)
  File "/Library/Frameworks/Python.framework/Versions/3.10/lib/python3.10/site-packages/django/db/backends/mysql/base.py", line 75, in execute
    return self.cursor.execute(query, args)
  File "/Library/Frameworks/Python.framework/Versions/3.10/lib/python3.10/site-packages/MySQLdb/cursors.py", line 179, in execute
    res = self._query(mogrified_query)
  File "/Library/Frameworks/Python.framework/Versions/3.10/lib/python3.10/site-packages/MySQLdb/cursors.py", line 330, in _query
    db.query(q)
  File "/Library/Frameworks/Python.framework/Versions/3.10/lib/python3.10/site-packages/MySQLdb/connections.py", line 255, in query
    _mysql.connection.query(self, query)
django.db.utils.OperationalError: (2013, 'Lost connection to MySQL server during query')
-------------------------------------
Fri Jan 19 10:33:00 JST 2024
Traceback (most recent call last):
  File "/Library/Frameworks/Python.framework/Versions/3.10/lib/python3.10/site-packages/selenium/webdriver/common/driver_finder.py", line 38, in get_path
    path = SeleniumManager().driver_location(options) if path is None else path
  File "/Library/Frameworks/Python.framework/Versions/3.10/lib/python3.10/site-packages/selenium/webdriver/common/selenium_manager.py", line 95, in driver_location
    output = self.run(args)
  File "/Library/Frameworks/Python.framework/Versions/3.10/lib/python3.10/site-packages/selenium/webdriver/common/selenium_manager.py", line 141, in run
    raise WebDriverException(f"Unsuccessful command executed: {command}.\n{result}{stderr}")
selenium.common.exceptions.WebDriverException: Message: Unsuccessful command executed: /Library/Frameworks/Python.framework/Versions/3.10/lib/python3.10/site-packages/selenium/webdriver/common/macos/selenium-manager --browser chrome --output json.
{'code': 65, 'message': 'error sending request for url (https://googlechromelabs.github.io/chrome-for-testing/known-good-versions-with-downloads.json): error trying to connect: dns error: failed to lookup address information: nodename nor servname provided, or not known', 'driver_path': '', 'browser_path': ''}


The above exception was the direct cause of the following exception:

Traceback (most recent call last):
  File "/Users/kimminseok/Library/Mobile Documents/com~apple~CloudDocs/Desktop/coding/LCKlol/manage.py", line 22, in <module>
    main()
  File "/Users/kimminseok/Library/Mobile Documents/com~apple~CloudDocs/Desktop/coding/LCKlol/manage.py", line 18, in main
    execute_from_command_line(sys.argv)
  File "/Library/Frameworks/Python.framework/Versions/3.10/lib/python3.10/site-packages/django/core/management/__init__.py", line 446, in execute_from_command_line
    utility.execute()
  File "/Library/Frameworks/Python.framework/Versions/3.10/lib/python3.10/site-packages/django/core/management/__init__.py", line 440, in execute
    self.fetch_command(subcommand).run_from_argv(self.argv)
  File "/Library/Frameworks/Python.framework/Versions/3.10/lib/python3.10/site-packages/django/core/management/base.py", line 414, in run_from_argv
    self.execute(*args, **cmd_options)
  File "/Library/Frameworks/Python.framework/Versions/3.10/lib/python3.10/site-packages/django/core/management/base.py", line 460, in execute
    output = self.handle(*args, **options)
  File "/Users/kimminseok/Library/Mobile Documents/com~apple~CloudDocs/Desktop/coding/LCKlol/index/management/commands/update.py", line 523, in handle
    self.update_schedule()
  File "/Users/kimminseok/Library/Mobile Documents/com~apple~CloudDocs/Desktop/coding/LCKlol/index/management/commands/update.py", line 26, in update_schedule
    driver = webdriver.Chrome(option)
  File "/Library/Frameworks/Python.framework/Versions/3.10/lib/python3.10/site-packages/selenium/webdriver/chrome/webdriver.py", line 45, in __init__
    super().__init__(
  File "/Library/Frameworks/Python.framework/Versions/3.10/lib/python3.10/site-packages/selenium/webdriver/chromium/webdriver.py", line 51, in __init__
    self.service.path = DriverFinder.get_path(self.service, options)
  File "/Library/Frameworks/Python.framework/Versions/3.10/lib/python3.10/site-packages/selenium/webdriver/common/driver_finder.py", line 41, in get_path
    raise NoSuchDriverException(msg) from err
selenium.common.exceptions.NoSuchDriverException: Message: Unable to obtain driver for chrome using Selenium Manager.; For documentation on this error, please visit: https://www.selenium.dev/documentation/webdriver/troubleshooting/errors/driver_location

-------------------------------------
Fri Jan 19 10:40:49 JST 2024
Traceback (most recent call last):
  File "/Library/Frameworks/Python.framework/Versions/3.10/lib/python3.10/site-packages/selenium/webdriver/common/driver_finder.py", line 38, in get_path
    path = SeleniumManager().driver_location(options) if path is None else path
  File "/Library/Frameworks/Python.framework/Versions/3.10/lib/python3.10/site-packages/selenium/webdriver/common/selenium_manager.py", line 95, in driver_location
    output = self.run(args)
  File "/Library/Frameworks/Python.framework/Versions/3.10/lib/python3.10/site-packages/selenium/webdriver/common/selenium_manager.py", line 141, in run
    raise WebDriverException(f"Unsuccessful command executed: {command}.\n{result}{stderr}")
selenium.common.exceptions.WebDriverException: Message: Unsuccessful command executed: /Library/Frameworks/Python.framework/Versions/3.10/lib/python3.10/site-packages/selenium/webdriver/common/macos/selenium-manager --browser chrome --output json.
{'code': 65, 'message': 'error sending request for url (https://googlechromelabs.github.io/chrome-for-testing/known-good-versions-with-downloads.json): error trying to connect: dns error: failed to lookup address information: nodename nor servname provided, or not known', 'driver_path': '', 'browser_path': ''}


The above exception was the direct cause of the following exception:

Traceback (most recent call last):
  File "/Users/kimminseok/Library/Mobile Documents/com~apple~CloudDocs/Desktop/coding/LCKlol/manage.py", line 22, in <module>
    main()
  File "/Users/kimminseok/Library/Mobile Documents/com~apple~CloudDocs/Desktop/coding/LCKlol/manage.py", line 18, in main
    execute_from_command_line(sys.argv)
  File "/Library/Frameworks/Python.framework/Versions/3.10/lib/python3.10/site-packages/django/core/management/__init__.py", line 446, in execute_from_command_line
    utility.execute()
  File "/Library/Frameworks/Python.framework/Versions/3.10/lib/python3.10/site-packages/django/core/management/__init__.py", line 440, in execute
    self.fetch_command(subcommand).run_from_argv(self.argv)
  File "/Library/Frameworks/Python.framework/Versions/3.10/lib/python3.10/site-packages/django/core/management/base.py", line 414, in run_from_argv
    self.execute(*args, **cmd_options)
  File "/Library/Frameworks/Python.framework/Versions/3.10/lib/python3.10/site-packages/django/core/management/base.py", line 460, in execute
    output = self.handle(*args, **options)
  File "/Users/kimminseok/Library/Mobile Documents/com~apple~CloudDocs/Desktop/coding/LCKlol/index/management/commands/update.py", line 523, in handle
    self.update_schedule()
  File "/Users/kimminseok/Library/Mobile Documents/com~apple~CloudDocs/Desktop/coding/LCKlol/index/management/commands/update.py", line 26, in update_schedule
    driver = webdriver.Chrome(option)
  File "/Library/Frameworks/Python.framework/Versions/3.10/lib/python3.10/site-packages/selenium/webdriver/chrome/webdriver.py", line 45, in __init__
    super().__init__(
  File "/Library/Frameworks/Python.framework/Versions/3.10/lib/python3.10/site-packages/selenium/webdriver/chromium/webdriver.py", line 51, in __init__
    self.service.path = DriverFinder.get_path(self.service, options)
  File "/Library/Frameworks/Python.framework/Versions/3.10/lib/python3.10/site-packages/selenium/webdriver/common/driver_finder.py", line 41, in get_path
    raise NoSuchDriverException(msg) from err
selenium.common.exceptions.NoSuchDriverException: Message: Unable to obtain driver for chrome using Selenium Manager.; For documentation on this error, please visit: https://www.selenium.dev/documentation/webdriver/troubleshooting/errors/driver_location

-------------------------------------
Fri Jan 19 10:41:00 JST 2024
Traceback (most recent call last):
  File "/Library/Frameworks/Python.framework/Versions/3.10/lib/python3.10/site-packages/selenium/webdriver/common/driver_finder.py", line 38, in get_path
    path = SeleniumManager().driver_location(options) if path is None else path
  File "/Library/Frameworks/Python.framework/Versions/3.10/lib/python3.10/site-packages/selenium/webdriver/common/selenium_manager.py", line 95, in driver_location
    output = self.run(args)
  File "/Library/Frameworks/Python.framework/Versions/3.10/lib/python3.10/site-packages/selenium/webdriver/common/selenium_manager.py", line 141, in run
    raise WebDriverException(f"Unsuccessful command executed: {command}.\n{result}{stderr}")
selenium.common.exceptions.WebDriverException: Message: Unsuccessful command executed: /Library/Frameworks/Python.framework/Versions/3.10/lib/python3.10/site-packages/selenium/webdriver/common/macos/selenium-manager --browser chrome --output json.
{'code': 65, 'message': 'error sending request for url (https://googlechromelabs.github.io/chrome-for-testing/known-good-versions-with-downloads.json): error trying to connect: dns error: failed to lookup address information: nodename nor servname provided, or not known', 'driver_path': '', 'browser_path': ''}


The above exception was the direct cause of the following exception:

Traceback (most recent call last):
  File "/Users/kimminseok/Library/Mobile Documents/com~apple~CloudDocs/Desktop/coding/LCKlol/manage.py", line 22, in <module>
    main()
  File "/Users/kimminseok/Library/Mobile Documents/com~apple~CloudDocs/Desktop/coding/LCKlol/manage.py", line 18, in main
    execute_from_command_line(sys.argv)
  File "/Library/Frameworks/Python.framework/Versions/3.10/lib/python3.10/site-packages/django/core/management/__init__.py", line 446, in execute_from_command_line
    utility.execute()
  File "/Library/Frameworks/Python.framework/Versions/3.10/lib/python3.10/site-packages/django/core/management/__init__.py", line 440, in execute
    self.fetch_command(subcommand).run_from_argv(self.argv)
  File "/Library/Frameworks/Python.framework/Versions/3.10/lib/python3.10/site-packages/django/core/management/base.py", line 414, in run_from_argv
    self.execute(*args, **cmd_options)
  File "/Library/Frameworks/Python.framework/Versions/3.10/lib/python3.10/site-packages/django/core/management/base.py", line 460, in execute
    output = self.handle(*args, **options)
  File "/Users/kimminseok/Library/Mobile Documents/com~apple~CloudDocs/Desktop/coding/LCKlol/index/management/commands/update.py", line 523, in handle
    self.update_schedule()
  File "/Users/kimminseok/Library/Mobile Documents/com~apple~CloudDocs/Desktop/coding/LCKlol/index/management/commands/update.py", line 26, in update_schedule
    driver = webdriver.Chrome(option)
  File "/Library/Frameworks/Python.framework/Versions/3.10/lib/python3.10/site-packages/selenium/webdriver/chrome/webdriver.py", line 45, in __init__
    super().__init__(
  File "/Library/Frameworks/Python.framework/Versions/3.10/lib/python3.10/site-packages/selenium/webdriver/chromium/webdriver.py", line 51, in __init__
    self.service.path = DriverFinder.get_path(self.service, options)
  File "/Library/Frameworks/Python.framework/Versions/3.10/lib/python3.10/site-packages/selenium/webdriver/common/driver_finder.py", line 41, in get_path
    raise NoSuchDriverException(msg) from err
selenium.common.exceptions.NoSuchDriverException: Message: Unable to obtain driver for chrome using Selenium Manager.; For documentation on this error, please visit: https://www.selenium.dev/documentation/webdriver/troubleshooting/errors/driver_location

-------------------------------------
Fri Jan 19 10:42:00 JST 2024
Traceback (most recent call last):
  File "/Library/Frameworks/Python.framework/Versions/3.10/lib/python3.10/site-packages/selenium/webdriver/common/driver_finder.py", line 38, in get_path
    path = SeleniumManager().driver_location(options) if path is None else path
  File "/Library/Frameworks/Python.framework/Versions/3.10/lib/python3.10/site-packages/selenium/webdriver/common/selenium_manager.py", line 95, in driver_location
    output = self.run(args)
  File "/Library/Frameworks/Python.framework/Versions/3.10/lib/python3.10/site-packages/selenium/webdriver/common/selenium_manager.py", line 141, in run
    raise WebDriverException(f"Unsuccessful command executed: {command}.\n{result}{stderr}")
selenium.common.exceptions.WebDriverException: Message: Unsuccessful command executed: /Library/Frameworks/Python.framework/Versions/3.10/lib/python3.10/site-packages/selenium/webdriver/common/macos/selenium-manager --browser chrome --output json.
{'code': 65, 'message': 'error sending request for url (https://googlechromelabs.github.io/chrome-for-testing/known-good-versions-with-downloads.json): error trying to connect: dns error: failed to lookup address information: nodename nor servname provided, or not known', 'driver_path': '', 'browser_path': ''}


The above exception was the direct cause of the following exception:

Traceback (most recent call last):
  File "/Users/kimminseok/Library/Mobile Documents/com~apple~CloudDocs/Desktop/coding/LCKlol/manage.py", line 22, in <module>
    main()
  File "/Users/kimminseok/Library/Mobile Documents/com~apple~CloudDocs/Desktop/coding/LCKlol/manage.py", line 18, in main
    execute_from_command_line(sys.argv)
  File "/Library/Frameworks/Python.framework/Versions/3.10/lib/python3.10/site-packages/django/core/management/__init__.py", line 446, in execute_from_command_line
    utility.execute()
  File "/Library/Frameworks/Python.framework/Versions/3.10/lib/python3.10/site-packages/django/core/management/__init__.py", line 440, in execute
    self.fetch_command(subcommand).run_from_argv(self.argv)
  File "/Library/Frameworks/Python.framework/Versions/3.10/lib/python3.10/site-packages/django/core/management/base.py", line 414, in run_from_argv
    self.execute(*args, **cmd_options)
  File "/Library/Frameworks/Python.framework/Versions/3.10/lib/python3.10/site-packages/django/core/management/base.py", line 460, in execute
    output = self.handle(*args, **options)
  File "/Users/kimminseok/Library/Mobile Documents/com~apple~CloudDocs/Desktop/coding/LCKlol/index/management/commands/update.py", line 523, in handle
    self.update_schedule()
  File "/Users/kimminseok/Library/Mobile Documents/com~apple~CloudDocs/Desktop/coding/LCKlol/index/management/commands/update.py", line 26, in update_schedule
    driver = webdriver.Chrome(option)
  File "/Library/Frameworks/Python.framework/Versions/3.10/lib/python3.10/site-packages/selenium/webdriver/chrome/webdriver.py", line 45, in __init__
    super().__init__(
  File "/Library/Frameworks/Python.framework/Versions/3.10/lib/python3.10/site-packages/selenium/webdriver/chromium/webdriver.py", line 51, in __init__
    self.service.path = DriverFinder.get_path(self.service, options)
  File "/Library/Frameworks/Python.framework/Versions/3.10/lib/python3.10/site-packages/selenium/webdriver/common/driver_finder.py", line 41, in get_path
    raise NoSuchDriverException(msg) from err
selenium.common.exceptions.NoSuchDriverException: Message: Unable to obtain driver for chrome using Selenium Manager.; For documentation on this error, please visit: https://www.selenium.dev/documentation/webdriver/troubleshooting/errors/driver_location

-------------------------------------
Fri Jan 19 10:43:00 JST 2024
Traceback (most recent call last):
  File "/Library/Frameworks/Python.framework/Versions/3.10/lib/python3.10/site-packages/selenium/webdriver/common/driver_finder.py", line 38, in get_path
    path = SeleniumManager().driver_location(options) if path is None else path
  File "/Library/Frameworks/Python.framework/Versions/3.10/lib/python3.10/site-packages/selenium/webdriver/common/selenium_manager.py", line 95, in driver_location
    output = self.run(args)
  File "/Library/Frameworks/Python.framework/Versions/3.10/lib/python3.10/site-packages/selenium/webdriver/common/selenium_manager.py", line 141, in run
    raise WebDriverException(f"Unsuccessful command executed: {command}.\n{result}{stderr}")
selenium.common.exceptions.WebDriverException: Message: Unsuccessful command executed: /Library/Frameworks/Python.framework/Versions/3.10/lib/python3.10/site-packages/selenium/webdriver/common/macos/selenium-manager --browser chrome --output json.
{'code': 65, 'message': 'error sending request for url (https://googlechromelabs.github.io/chrome-for-testing/known-good-versions-with-downloads.json): error trying to connect: dns error: failed to lookup address information: nodename nor servname provided, or not known', 'driver_path': '', 'browser_path': ''}


The above exception was the direct cause of the following exception:

Traceback (most recent call last):
  File "/Users/kimminseok/Library/Mobile Documents/com~apple~CloudDocs/Desktop/coding/LCKlol/manage.py", line 22, in <module>
    main()
  File "/Users/kimminseok/Library/Mobile Documents/com~apple~CloudDocs/Desktop/coding/LCKlol/manage.py", line 18, in main
    execute_from_command_line(sys.argv)
  File "/Library/Frameworks/Python.framework/Versions/3.10/lib/python3.10/site-packages/django/core/management/__init__.py", line 446, in execute_from_command_line
    utility.execute()
  File "/Library/Frameworks/Python.framework/Versions/3.10/lib/python3.10/site-packages/django/core/management/__init__.py", line 440, in execute
    self.fetch_command(subcommand).run_from_argv(self.argv)
  File "/Library/Frameworks/Python.framework/Versions/3.10/lib/python3.10/site-packages/django/core/management/base.py", line 414, in run_from_argv
    self.execute(*args, **cmd_options)
  File "/Library/Frameworks/Python.framework/Versions/3.10/lib/python3.10/site-packages/django/core/management/base.py", line 460, in execute
    output = self.handle(*args, **options)
  File "/Users/kimminseok/Library/Mobile Documents/com~apple~CloudDocs/Desktop/coding/LCKlol/index/management/commands/update.py", line 523, in handle
    self.update_schedule()
  File "/Users/kimminseok/Library/Mobile Documents/com~apple~CloudDocs/Desktop/coding/LCKlol/index/management/commands/update.py", line 26, in update_schedule
    driver = webdriver.Chrome(option)
  File "/Library/Frameworks/Python.framework/Versions/3.10/lib/python3.10/site-packages/selenium/webdriver/chrome/webdriver.py", line 45, in __init__
    super().__init__(
  File "/Library/Frameworks/Python.framework/Versions/3.10/lib/python3.10/site-packages/selenium/webdriver/chromium/webdriver.py", line 51, in __init__
    self.service.path = DriverFinder.get_path(self.service, options)
  File "/Library/Frameworks/Python.framework/Versions/3.10/lib/python3.10/site-packages/selenium/webdriver/common/driver_finder.py", line 41, in get_path
    raise NoSuchDriverException(msg) from err
selenium.common.exceptions.NoSuchDriverException: Message: Unable to obtain driver for chrome using Selenium Manager.; For documentation on this error, please visit: https://www.selenium.dev/documentation/webdriver/troubleshooting/errors/driver_location

-------------------------------------
Fri Jan 19 10:44:00 JST 2024
Traceback (most recent call last):
  File "/Library/Frameworks/Python.framework/Versions/3.10/lib/python3.10/site-packages/django/db/backends/base/base.py", line 244, in ensure_connection
    self.connect()
  File "/Library/Frameworks/Python.framework/Versions/3.10/lib/python3.10/site-packages/django/utils/asyncio.py", line 26, in inner
    return func(*args, **kwargs)
  File "/Library/Frameworks/Python.framework/Versions/3.10/lib/python3.10/site-packages/django/db/backends/base/base.py", line 225, in connect
    self.connection = self.get_new_connection(conn_params)
  File "/Library/Frameworks/Python.framework/Versions/3.10/lib/python3.10/site-packages/django/utils/asyncio.py", line 26, in inner
    return func(*args, **kwargs)
  File "/Library/Frameworks/Python.framework/Versions/3.10/lib/python3.10/site-packages/django/db/backends/mysql/base.py", line 244, in get_new_connection
    connection = Database.connect(**conn_params)
  File "/Library/Frameworks/Python.framework/Versions/3.10/lib/python3.10/site-packages/MySQLdb/__init__.py", line 121, in Connect
    return Connection(*args, **kwargs)
  File "/Library/Frameworks/Python.framework/Versions/3.10/lib/python3.10/site-packages/MySQLdb/connections.py", line 193, in __init__
    super().__init__(*args, **kwargs2)
MySQLdb.OperationalError: (1130, "Host '211.36.142.246' is not allowed to connect to this MySQL server")

The above exception was the direct cause of the following exception:

Traceback (most recent call last):
  File "/Users/kimminseok/Library/Mobile Documents/com~apple~CloudDocs/Desktop/coding/LCKlol/manage.py", line 22, in <module>
    main()
  File "/Users/kimminseok/Library/Mobile Documents/com~apple~CloudDocs/Desktop/coding/LCKlol/manage.py", line 18, in main
    execute_from_command_line(sys.argv)
  File "/Library/Frameworks/Python.framework/Versions/3.10/lib/python3.10/site-packages/django/core/management/__init__.py", line 446, in execute_from_command_line
    utility.execute()
  File "/Library/Frameworks/Python.framework/Versions/3.10/lib/python3.10/site-packages/django/core/management/__init__.py", line 440, in execute
    self.fetch_command(subcommand).run_from_argv(self.argv)
  File "/Library/Frameworks/Python.framework/Versions/3.10/lib/python3.10/site-packages/django/core/management/base.py", line 414, in run_from_argv
    self.execute(*args, **cmd_options)
  File "/Library/Frameworks/Python.framework/Versions/3.10/lib/python3.10/site-packages/django/core/management/base.py", line 460, in execute
    output = self.handle(*args, **options)
  File "/Users/kimminseok/Library/Mobile Documents/com~apple~CloudDocs/Desktop/coding/LCKlol/index/management/commands/update.py", line 523, in handle
    self.update_schedule()
  File "/Users/kimminseok/Library/Mobile Documents/com~apple~CloudDocs/Desktop/coding/LCKlol/index/management/commands/update.py", line 113, in update_schedule
    schedule = Schedule.objects.get(year=year, month=month, day=day, team1_name=team1_name, team2_name=team2_name, hour=hour, min=min, ampm=ampm)
  File "/Library/Frameworks/Python.framework/Versions/3.10/lib/python3.10/site-packages/django/db/models/manager.py", line 85, in manager_method
    return getattr(self.get_queryset(), name)(*args, **kwargs)
  File "/Library/Frameworks/Python.framework/Versions/3.10/lib/python3.10/site-packages/django/db/models/query.py", line 492, in get
    num = len(clone)
  File "/Library/Frameworks/Python.framework/Versions/3.10/lib/python3.10/site-packages/django/db/models/query.py", line 302, in __len__
    self._fetch_all()
  File "/Library/Frameworks/Python.framework/Versions/3.10/lib/python3.10/site-packages/django/db/models/query.py", line 1507, in _fetch_all
    self._result_cache = list(self._iterable_class(self))
  File "/Library/Frameworks/Python.framework/Versions/3.10/lib/python3.10/site-packages/django/db/models/query.py", line 57, in __iter__
    results = compiler.execute_sql(
  File "/Library/Frameworks/Python.framework/Versions/3.10/lib/python3.10/site-packages/django/db/models/sql/compiler.py", line 1359, in execute_sql
    cursor = self.connection.cursor()
  File "/Library/Frameworks/Python.framework/Versions/3.10/lib/python3.10/site-packages/django/utils/asyncio.py", line 26, in inner
    return func(*args, **kwargs)
  File "/Library/Frameworks/Python.framework/Versions/3.10/lib/python3.10/site-packages/django/db/backends/base/base.py", line 284, in cursor
    return self._cursor()
  File "/Library/Frameworks/Python.framework/Versions/3.10/lib/python3.10/site-packages/django/db/backends/base/base.py", line 260, in _cursor
    self.ensure_connection()
  File "/Library/Frameworks/Python.framework/Versions/3.10/lib/python3.10/site-packages/django/utils/asyncio.py", line 26, in inner
    return func(*args, **kwargs)
  File "/Library/Frameworks/Python.framework/Versions/3.10/lib/python3.10/site-packages/django/db/backends/base/base.py", line 243, in ensure_connection
    with self.wrap_database_errors:
  File "/Library/Frameworks/Python.framework/Versions/3.10/lib/python3.10/site-packages/django/db/utils.py", line 91, in __exit__
    raise dj_exc_value.with_traceback(traceback) from exc_value
  File "/Library/Frameworks/Python.framework/Versions/3.10/lib/python3.10/site-packages/django/db/backends/base/base.py", line 244, in ensure_connection
    self.connect()
  File "/Library/Frameworks/Python.framework/Versions/3.10/lib/python3.10/site-packages/django/utils/asyncio.py", line 26, in inner
    return func(*args, **kwargs)
  File "/Library/Frameworks/Python.framework/Versions/3.10/lib/python3.10/site-packages/django/db/backends/base/base.py", line 225, in connect
    self.connection = self.get_new_connection(conn_params)
  File "/Library/Frameworks/Python.framework/Versions/3.10/lib/python3.10/site-packages/django/utils/asyncio.py", line 26, in inner
    return func(*args, **kwargs)
  File "/Library/Frameworks/Python.framework/Versions/3.10/lib/python3.10/site-packages/django/db/backends/mysql/base.py", line 244, in get_new_connection
    connection = Database.connect(**conn_params)
  File "/Library/Frameworks/Python.framework/Versions/3.10/lib/python3.10/site-packages/MySQLdb/__init__.py", line 121, in Connect
    return Connection(*args, **kwargs)
  File "/Library/Frameworks/Python.framework/Versions/3.10/lib/python3.10/site-packages/MySQLdb/connections.py", line 193, in __init__
    super().__init__(*args, **kwargs2)
django.db.utils.OperationalError: (1130, "Host '211.36.142.246' is not allowed to connect to this MySQL server")
-------------------------------------
Fri Jan 19 10:45:00 JST 2024
Traceback (most recent call last):
  File "/Library/Frameworks/Python.framework/Versions/3.10/lib/python3.10/site-packages/django/db/backends/base/base.py", line 244, in ensure_connection
    self.connect()
  File "/Library/Frameworks/Python.framework/Versions/3.10/lib/python3.10/site-packages/django/utils/asyncio.py", line 26, in inner
    return func(*args, **kwargs)
  File "/Library/Frameworks/Python.framework/Versions/3.10/lib/python3.10/site-packages/django/db/backends/base/base.py", line 225, in connect
    self.connection = self.get_new_connection(conn_params)
  File "/Library/Frameworks/Python.framework/Versions/3.10/lib/python3.10/site-packages/django/utils/asyncio.py", line 26, in inner
    return func(*args, **kwargs)
  File "/Library/Frameworks/Python.framework/Versions/3.10/lib/python3.10/site-packages/django/db/backends/mysql/base.py", line 244, in get_new_connection
    connection = Database.connect(**conn_params)
  File "/Library/Frameworks/Python.framework/Versions/3.10/lib/python3.10/site-packages/MySQLdb/__init__.py", line 121, in Connect
    return Connection(*args, **kwargs)
  File "/Library/Frameworks/Python.framework/Versions/3.10/lib/python3.10/site-packages/MySQLdb/connections.py", line 193, in __init__
    super().__init__(*args, **kwargs2)
MySQLdb.OperationalError: (1130, "Host '211.36.142.246' is not allowed to connect to this MySQL server")

The above exception was the direct cause of the following exception:

Traceback (most recent call last):
  File "/Users/kimminseok/Library/Mobile Documents/com~apple~CloudDocs/Desktop/coding/LCKlol/manage.py", line 22, in <module>
    main()
  File "/Users/kimminseok/Library/Mobile Documents/com~apple~CloudDocs/Desktop/coding/LCKlol/manage.py", line 18, in main
    execute_from_command_line(sys.argv)
  File "/Library/Frameworks/Python.framework/Versions/3.10/lib/python3.10/site-packages/django/core/management/__init__.py", line 446, in execute_from_command_line
    utility.execute()
  File "/Library/Frameworks/Python.framework/Versions/3.10/lib/python3.10/site-packages/django/core/management/__init__.py", line 440, in execute
    self.fetch_command(subcommand).run_from_argv(self.argv)
  File "/Library/Frameworks/Python.framework/Versions/3.10/lib/python3.10/site-packages/django/core/management/base.py", line 414, in run_from_argv
    self.execute(*args, **cmd_options)
  File "/Library/Frameworks/Python.framework/Versions/3.10/lib/python3.10/site-packages/django/core/management/base.py", line 460, in execute
    output = self.handle(*args, **options)
  File "/Users/kimminseok/Library/Mobile Documents/com~apple~CloudDocs/Desktop/coding/LCKlol/index/management/commands/update.py", line 523, in handle
    self.update_schedule()
  File "/Users/kimminseok/Library/Mobile Documents/com~apple~CloudDocs/Desktop/coding/LCKlol/index/management/commands/update.py", line 113, in update_schedule
    schedule = Schedule.objects.get(year=year, month=month, day=day, team1_name=team1_name, team2_name=team2_name, hour=hour, min=min, ampm=ampm)
  File "/Library/Frameworks/Python.framework/Versions/3.10/lib/python3.10/site-packages/django/db/models/manager.py", line 85, in manager_method
    return getattr(self.get_queryset(), name)(*args, **kwargs)
  File "/Library/Frameworks/Python.framework/Versions/3.10/lib/python3.10/site-packages/django/db/models/query.py", line 492, in get
    num = len(clone)
  File "/Library/Frameworks/Python.framework/Versions/3.10/lib/python3.10/site-packages/django/db/models/query.py", line 302, in __len__
    self._fetch_all()
  File "/Library/Frameworks/Python.framework/Versions/3.10/lib/python3.10/site-packages/django/db/models/query.py", line 1507, in _fetch_all
    self._result_cache = list(self._iterable_class(self))
  File "/Library/Frameworks/Python.framework/Versions/3.10/lib/python3.10/site-packages/django/db/models/query.py", line 57, in __iter__
    results = compiler.execute_sql(
  File "/Library/Frameworks/Python.framework/Versions/3.10/lib/python3.10/site-packages/django/db/models/sql/compiler.py", line 1359, in execute_sql
    cursor = self.connection.cursor()
  File "/Library/Frameworks/Python.framework/Versions/3.10/lib/python3.10/site-packages/django/utils/asyncio.py", line 26, in inner
    return func(*args, **kwargs)
  File "/Library/Frameworks/Python.framework/Versions/3.10/lib/python3.10/site-packages/django/db/backends/base/base.py", line 284, in cursor
    return self._cursor()
  File "/Library/Frameworks/Python.framework/Versions/3.10/lib/python3.10/site-packages/django/db/backends/base/base.py", line 260, in _cursor
    self.ensure_connection()
  File "/Library/Frameworks/Python.framework/Versions/3.10/lib/python3.10/site-packages/django/utils/asyncio.py", line 26, in inner
    return func(*args, **kwargs)
  File "/Library/Frameworks/Python.framework/Versions/3.10/lib/python3.10/site-packages/django/db/backends/base/base.py", line 243, in ensure_connection
    with self.wrap_database_errors:
  File "/Library/Frameworks/Python.framework/Versions/3.10/lib/python3.10/site-packages/django/db/utils.py", line 91, in __exit__
    raise dj_exc_value.with_traceback(traceback) from exc_value
  File "/Library/Frameworks/Python.framework/Versions/3.10/lib/python3.10/site-packages/django/db/backends/base/base.py", line 244, in ensure_connection
    self.connect()
  File "/Library/Frameworks/Python.framework/Versions/3.10/lib/python3.10/site-packages/django/utils/asyncio.py", line 26, in inner
    return func(*args, **kwargs)
  File "/Library/Frameworks/Python.framework/Versions/3.10/lib/python3.10/site-packages/django/db/backends/base/base.py", line 225, in connect
    self.connection = self.get_new_connection(conn_params)
  File "/Library/Frameworks/Python.framework/Versions/3.10/lib/python3.10/site-packages/django/utils/asyncio.py", line 26, in inner
    return func(*args, **kwargs)
  File "/Library/Frameworks/Python.framework/Versions/3.10/lib/python3.10/site-packages/django/db/backends/mysql/base.py", line 244, in get_new_connection
    connection = Database.connect(**conn_params)
  File "/Library/Frameworks/Python.framework/Versions/3.10/lib/python3.10/site-packages/MySQLdb/__init__.py", line 121, in Connect
    return Connection(*args, **kwargs)
  File "/Library/Frameworks/Python.framework/Versions/3.10/lib/python3.10/site-packages/MySQLdb/connections.py", line 193, in __init__
    super().__init__(*args, **kwargs2)
django.db.utils.OperationalError: (1130, "Host '211.36.142.246' is not allowed to connect to this MySQL server")
-------------------------------------
Traceback (most recent call last):
  File "/Users/kimminseok/Library/Mobile Documents/com~apple~CloudDocs/Desktop/coding/LCKlol/manage.py", line 22, in <module>
    main()
  File "/Users/kimminseok/Library/Mobile Documents/com~apple~CloudDocs/Desktop/coding/LCKlol/manage.py", line 18, in main
    execute_from_command_line(sys.argv)
  File "/Library/Frameworks/Python.framework/Versions/3.10/lib/python3.10/site-packages/django/core/management/__init__.py", line 446, in execute_from_command_line
    utility.execute()
  File "/Library/Frameworks/Python.framework/Versions/3.10/lib/python3.10/site-packages/django/core/management/__init__.py", line 440, in execute
    self.fetch_command(subcommand).run_from_argv(self.argv)
  File "/Library/Frameworks/Python.framework/Versions/3.10/lib/python3.10/site-packages/django/core/management/base.py", line 414, in run_from_argv
    self.execute(*args, **cmd_options)
  File "/Library/Frameworks/Python.framework/Versions/3.10/lib/python3.10/site-packages/django/core/management/base.py", line 460, in execute
    output = self.handle(*args, **options)
  File "/Users/kimminseok/Library/Mobile Documents/com~apple~CloudDocs/Desktop/coding/LCKlol/index/management/commands/update.py", line 523, in handle
    self.update_schedule()
  File "/Users/kimminseok/Library/Mobile Documents/com~apple~CloudDocs/Desktop/coding/LCKlol/index/management/commands/update.py", line 35, in update_schedule
    web_source = driver.page_source
  File "/Library/Frameworks/Python.framework/Versions/3.10/lib/python3.10/site-packages/selenium/webdriver/remote/webdriver.py", line 445, in page_source
    return self.execute(Command.GET_PAGE_SOURCE)["value"]
  File "/Library/Frameworks/Python.framework/Versions/3.10/lib/python3.10/site-packages/selenium/webdriver/remote/webdriver.py", line 344, in execute
    self.error_handler.check_response(response)
  File "/Library/Frameworks/Python.framework/Versions/3.10/lib/python3.10/site-packages/selenium/webdriver/remote/errorhandler.py", line 229, in check_response
    raise exception_class(message, screen, stacktrace)
selenium.common.exceptions.WebDriverException: Message: disconnected: not connected to DevTools
  (failed to check if window was closed: disconnected: not connected to DevTools)
  (Session info: chrome-headless-shell=120.0.6099.216)
Stacktrace:
0   chromedriver                        0x00000001024404dc chromedriver + 4162780
1   chromedriver                        0x0000000102438664 chromedriver + 4130404
2   chromedriver                        0x000000010208fbc0 chromedriver + 293824
3   chromedriver                        0x00000001020770b0 chromedriver + 192688
4   chromedriver                        0x0000000102076fd8 chromedriver + 192472
5   chromedriver                        0x00000001021152b0 chromedriver + 840368
6   chromedriver                        0x00000001020c96bc chromedriver + 530108
7   chromedriver                        0x00000001020ca930 chromedriver + 534832
8   chromedriver                        0x0000000102405e08 chromedriver + 3923464
9   chromedriver                        0x000000010240a3dc chromedriver + 3941340
10  chromedriver                        0x00000001023ee038 chromedriver + 3825720
11  chromedriver                        0x000000010240af3c chromedriver + 3944252
12  chromedriver                        0x00000001023e06f4 chromedriver + 3770100
13  chromedriver                        0x0000000102427980 chromedriver + 4061568
14  chromedriver                        0x0000000102427af8 chromedriver + 4061944
15  chromedriver                        0x00000001024382e4 chromedriver + 4129508
16  libsystem_pthread.dylib             0x0000000183ba2034 _pthread_start + 136
17  libsystem_pthread.dylib             0x0000000183b9ce3c thread_start + 8

-------------------------------------
Fri Jan 19 11:00:00 JST 2024
Traceback (most recent call last):
  File "/Library/Frameworks/Python.framework/Versions/3.10/lib/python3.10/site-packages/django/db/backends/base/base.py", line 244, in ensure_connection
    self.connect()
  File "/Library/Frameworks/Python.framework/Versions/3.10/lib/python3.10/site-packages/django/utils/asyncio.py", line 26, in inner
    return func(*args, **kwargs)
  File "/Library/Frameworks/Python.framework/Versions/3.10/lib/python3.10/site-packages/django/db/backends/base/base.py", line 225, in connect
    self.connection = self.get_new_connection(conn_params)
  File "/Library/Frameworks/Python.framework/Versions/3.10/lib/python3.10/site-packages/django/utils/asyncio.py", line 26, in inner
    return func(*args, **kwargs)
  File "/Library/Frameworks/Python.framework/Versions/3.10/lib/python3.10/site-packages/django/db/backends/mysql/base.py", line 244, in get_new_connection
    connection = Database.connect(**conn_params)
  File "/Library/Frameworks/Python.framework/Versions/3.10/lib/python3.10/site-packages/MySQLdb/__init__.py", line 121, in Connect
    return Connection(*args, **kwargs)
  File "/Library/Frameworks/Python.framework/Versions/3.10/lib/python3.10/site-packages/MySQLdb/connections.py", line 193, in __init__
    super().__init__(*args, **kwargs2)
MySQLdb.OperationalError: (1130, "Host '211.36.142.246' is not allowed to connect to this MySQL server")

The above exception was the direct cause of the following exception:

Traceback (most recent call last):
  File "/Users/kimminseok/Library/Mobile Documents/com~apple~CloudDocs/Desktop/coding/LCKlol/manage.py", line 22, in <module>
    main()
  File "/Users/kimminseok/Library/Mobile Documents/com~apple~CloudDocs/Desktop/coding/LCKlol/manage.py", line 18, in main
    execute_from_command_line(sys.argv)
  File "/Library/Frameworks/Python.framework/Versions/3.10/lib/python3.10/site-packages/django/core/management/__init__.py", line 446, in execute_from_command_line
    utility.execute()
  File "/Library/Frameworks/Python.framework/Versions/3.10/lib/python3.10/site-packages/django/core/management/__init__.py", line 440, in execute
    self.fetch_command(subcommand).run_from_argv(self.argv)
  File "/Library/Frameworks/Python.framework/Versions/3.10/lib/python3.10/site-packages/django/core/management/base.py", line 414, in run_from_argv
    self.execute(*args, **cmd_options)
  File "/Library/Frameworks/Python.framework/Versions/3.10/lib/python3.10/site-packages/django/core/management/base.py", line 460, in execute
    output = self.handle(*args, **options)
  File "/Users/kimminseok/Library/Mobile Documents/com~apple~CloudDocs/Desktop/coding/LCKlol/index/management/commands/update.py", line 523, in handle
    self.update_schedule()
  File "/Users/kimminseok/Library/Mobile Documents/com~apple~CloudDocs/Desktop/coding/LCKlol/index/management/commands/update.py", line 113, in update_schedule
    schedule = Schedule.objects.get(year=year, month=month, day=day, team1_name=team1_name, team2_name=team2_name, hour=hour, min=min, ampm=ampm)
  File "/Library/Frameworks/Python.framework/Versions/3.10/lib/python3.10/site-packages/django/db/models/manager.py", line 85, in manager_method
    return getattr(self.get_queryset(), name)(*args, **kwargs)
  File "/Library/Frameworks/Python.framework/Versions/3.10/lib/python3.10/site-packages/django/db/models/query.py", line 492, in get
    num = len(clone)
  File "/Library/Frameworks/Python.framework/Versions/3.10/lib/python3.10/site-packages/django/db/models/query.py", line 302, in __len__
    self._fetch_all()
  File "/Library/Frameworks/Python.framework/Versions/3.10/lib/python3.10/site-packages/django/db/models/query.py", line 1507, in _fetch_all
    self._result_cache = list(self._iterable_class(self))
  File "/Library/Frameworks/Python.framework/Versions/3.10/lib/python3.10/site-packages/django/db/models/query.py", line 57, in __iter__
    results = compiler.execute_sql(
  File "/Library/Frameworks/Python.framework/Versions/3.10/lib/python3.10/site-packages/django/db/models/sql/compiler.py", line 1359, in execute_sql
    cursor = self.connection.cursor()
  File "/Library/Frameworks/Python.framework/Versions/3.10/lib/python3.10/site-packages/django/utils/asyncio.py", line 26, in inner
    return func(*args, **kwargs)
  File "/Library/Frameworks/Python.framework/Versions/3.10/lib/python3.10/site-packages/django/db/backends/base/base.py", line 284, in cursor
    return self._cursor()
  File "/Library/Frameworks/Python.framework/Versions/3.10/lib/python3.10/site-packages/django/db/backends/base/base.py", line 260, in _cursor
    self.ensure_connection()
  File "/Library/Frameworks/Python.framework/Versions/3.10/lib/python3.10/site-packages/django/utils/asyncio.py", line 26, in inner
    return func(*args, **kwargs)
  File "/Library/Frameworks/Python.framework/Versions/3.10/lib/python3.10/site-packages/django/db/backends/base/base.py", line 243, in ensure_connection
    with self.wrap_database_errors:
  File "/Library/Frameworks/Python.framework/Versions/3.10/lib/python3.10/site-packages/django/db/utils.py", line 91, in __exit__
    raise dj_exc_value.with_traceback(traceback) from exc_value
  File "/Library/Frameworks/Python.framework/Versions/3.10/lib/python3.10/site-packages/django/db/backends/base/base.py", line 244, in ensure_connection
    self.connect()
  File "/Library/Frameworks/Python.framework/Versions/3.10/lib/python3.10/site-packages/django/utils/asyncio.py", line 26, in inner
    return func(*args, **kwargs)
  File "/Library/Frameworks/Python.framework/Versions/3.10/lib/python3.10/site-packages/django/db/backends/base/base.py", line 225, in connect
    self.connection = self.get_new_connection(conn_params)
  File "/Library/Frameworks/Python.framework/Versions/3.10/lib/python3.10/site-packages/django/utils/asyncio.py", line 26, in inner
    return func(*args, **kwargs)
  File "/Library/Frameworks/Python.framework/Versions/3.10/lib/python3.10/site-packages/django/db/backends/mysql/base.py", line 244, in get_new_connection
    connection = Database.connect(**conn_params)
  File "/Library/Frameworks/Python.framework/Versions/3.10/lib/python3.10/site-packages/MySQLdb/__init__.py", line 121, in Connect
    return Connection(*args, **kwargs)
  File "/Library/Frameworks/Python.framework/Versions/3.10/lib/python3.10/site-packages/MySQLdb/connections.py", line 193, in __init__
    super().__init__(*args, **kwargs2)
django.db.utils.OperationalError: (1130, "Host '211.36.142.246' is not allowed to connect to this MySQL server")
-------------------------------------
update schedule complete
update champion complete
Traceback (most recent call last):
  File "/Library/Frameworks/Python.framework/Versions/3.10/lib/python3.10/site-packages/django/db/backends/utils.py", line 89, in _execute
    return self.cursor.execute(sql, params)
  File "/Library/Frameworks/Python.framework/Versions/3.10/lib/python3.10/site-packages/django/db/backends/mysql/base.py", line 75, in execute
    return self.cursor.execute(query, args)
  File "/Library/Frameworks/Python.framework/Versions/3.10/lib/python3.10/site-packages/MySQLdb/cursors.py", line 179, in execute
    res = self._query(mogrified_query)
  File "/Library/Frameworks/Python.framework/Versions/3.10/lib/python3.10/site-packages/MySQLdb/cursors.py", line 330, in _query
    db.query(q)
  File "/Library/Frameworks/Python.framework/Versions/3.10/lib/python3.10/site-packages/MySQLdb/connections.py", line 255, in query
    _mysql.connection.query(self, query)
MySQLdb.OperationalError: (2013, 'Lost connection to MySQL server during query')

The above exception was the direct cause of the following exception:

Traceback (most recent call last):
  File "/Users/kimminseok/Library/Mobile Documents/com~apple~CloudDocs/Desktop/coding/LCKlol/manage.py", line 22, in <module>
    main()
  File "/Users/kimminseok/Library/Mobile Documents/com~apple~CloudDocs/Desktop/coding/LCKlol/manage.py", line 18, in main
    execute_from_command_line(sys.argv)
  File "/Library/Frameworks/Python.framework/Versions/3.10/lib/python3.10/site-packages/django/core/management/__init__.py", line 446, in execute_from_command_line
    utility.execute()
  File "/Library/Frameworks/Python.framework/Versions/3.10/lib/python3.10/site-packages/django/core/management/__init__.py", line 440, in execute
    self.fetch_command(subcommand).run_from_argv(self.argv)
  File "/Library/Frameworks/Python.framework/Versions/3.10/lib/python3.10/site-packages/django/core/management/base.py", line 414, in run_from_argv
    self.execute(*args, **cmd_options)
  File "/Library/Frameworks/Python.framework/Versions/3.10/lib/python3.10/site-packages/django/core/management/base.py", line 460, in execute
    output = self.handle(*args, **options)
  File "/Users/kimminseok/Library/Mobile Documents/com~apple~CloudDocs/Desktop/coding/LCKlol/index/management/commands/update.py", line 527, in handle
    self.update_ranking_24_spring_regular()
  File "/Users/kimminseok/Library/Mobile Documents/com~apple~CloudDocs/Desktop/coding/LCKlol/index/management/commands/update.py", line 498, in update_ranking_24_spring_regular
    team2 = self.convert_team_name_24(Ranking_24_spring_regular.objects.get(name=schedule_object.team2_name))
  File "/Library/Frameworks/Python.framework/Versions/3.10/lib/python3.10/site-packages/django/db/models/manager.py", line 85, in manager_method
    return getattr(self.get_queryset(), name)(*args, **kwargs)
  File "/Library/Frameworks/Python.framework/Versions/3.10/lib/python3.10/site-packages/django/db/models/query.py", line 492, in get
    num = len(clone)
  File "/Library/Frameworks/Python.framework/Versions/3.10/lib/python3.10/site-packages/django/db/models/query.py", line 302, in __len__
    self._fetch_all()
  File "/Library/Frameworks/Python.framework/Versions/3.10/lib/python3.10/site-packages/django/db/models/query.py", line 1507, in _fetch_all
    self._result_cache = list(self._iterable_class(self))
  File "/Library/Frameworks/Python.framework/Versions/3.10/lib/python3.10/site-packages/django/db/models/query.py", line 57, in __iter__
    results = compiler.execute_sql(
  File "/Library/Frameworks/Python.framework/Versions/3.10/lib/python3.10/site-packages/django/db/models/sql/compiler.py", line 1361, in execute_sql
    cursor.execute(sql, params)
  File "/Library/Frameworks/Python.framework/Versions/3.10/lib/python3.10/site-packages/django/db/backends/utils.py", line 103, in execute
    return super().execute(sql, params)
  File "/Library/Frameworks/Python.framework/Versions/3.10/lib/python3.10/site-packages/django/db/backends/utils.py", line 67, in execute
    return self._execute_with_wrappers(
  File "/Library/Frameworks/Python.framework/Versions/3.10/lib/python3.10/site-packages/django/db/backends/utils.py", line 80, in _execute_with_wrappers
    return executor(sql, params, many, context)
  File "/Library/Frameworks/Python.framework/Versions/3.10/lib/python3.10/site-packages/django/db/backends/utils.py", line 84, in _execute
    with self.db.wrap_database_errors:
  File "/Library/Frameworks/Python.framework/Versions/3.10/lib/python3.10/site-packages/django/db/utils.py", line 91, in __exit__
    raise dj_exc_value.with_traceback(traceback) from exc_value
  File "/Library/Frameworks/Python.framework/Versions/3.10/lib/python3.10/site-packages/django/db/backends/utils.py", line 89, in _execute
    return self.cursor.execute(sql, params)
  File "/Library/Frameworks/Python.framework/Versions/3.10/lib/python3.10/site-packages/django/db/backends/mysql/base.py", line 75, in execute
    return self.cursor.execute(query, args)
  File "/Library/Frameworks/Python.framework/Versions/3.10/lib/python3.10/site-packages/MySQLdb/cursors.py", line 179, in execute
    res = self._query(mogrified_query)
  File "/Library/Frameworks/Python.framework/Versions/3.10/lib/python3.10/site-packages/MySQLdb/cursors.py", line 330, in _query
    db.query(q)
  File "/Library/Frameworks/Python.framework/Versions/3.10/lib/python3.10/site-packages/MySQLdb/connections.py", line 255, in query
    _mysql.connection.query(self, query)
django.db.utils.OperationalError: (2013, 'Lost connection to MySQL server during query')
-------------------------------------
update schedule complete
update champion complete
Traceback (most recent call last):
  File "/Library/Frameworks/Python.framework/Versions/3.10/lib/python3.10/site-packages/django/db/backends/utils.py", line 89, in _execute
    return self.cursor.execute(sql, params)
  File "/Library/Frameworks/Python.framework/Versions/3.10/lib/python3.10/site-packages/django/db/backends/mysql/base.py", line 75, in execute
    return self.cursor.execute(query, args)
  File "/Library/Frameworks/Python.framework/Versions/3.10/lib/python3.10/site-packages/MySQLdb/cursors.py", line 179, in execute
    res = self._query(mogrified_query)
  File "/Library/Frameworks/Python.framework/Versions/3.10/lib/python3.10/site-packages/MySQLdb/cursors.py", line 330, in _query
    db.query(q)
  File "/Library/Frameworks/Python.framework/Versions/3.10/lib/python3.10/site-packages/MySQLdb/connections.py", line 255, in query
    _mysql.connection.query(self, query)
MySQLdb.OperationalError: (2013, 'Lost connection to MySQL server during query')

The above exception was the direct cause of the following exception:

Traceback (most recent call last):
  File "/Users/kimminseok/Library/Mobile Documents/com~apple~CloudDocs/Desktop/coding/LCKlol/manage.py", line 22, in <module>
    main()
  File "/Users/kimminseok/Library/Mobile Documents/com~apple~CloudDocs/Desktop/coding/LCKlol/manage.py", line 18, in main
    execute_from_command_line(sys.argv)
  File "/Library/Frameworks/Python.framework/Versions/3.10/lib/python3.10/site-packages/django/core/management/__init__.py", line 446, in execute_from_command_line
    utility.execute()
  File "/Library/Frameworks/Python.framework/Versions/3.10/lib/python3.10/site-packages/django/core/management/__init__.py", line 440, in execute
    self.fetch_command(subcommand).run_from_argv(self.argv)
  File "/Library/Frameworks/Python.framework/Versions/3.10/lib/python3.10/site-packages/django/core/management/base.py", line 414, in run_from_argv
    self.execute(*args, **cmd_options)
  File "/Library/Frameworks/Python.framework/Versions/3.10/lib/python3.10/site-packages/django/core/management/base.py", line 460, in execute
    output = self.handle(*args, **options)
  File "/Users/kimminseok/Library/Mobile Documents/com~apple~CloudDocs/Desktop/coding/LCKlol/index/management/commands/update.py", line 527, in handle
    self.update_ranking_24_spring_regular()
  File "/Users/kimminseok/Library/Mobile Documents/com~apple~CloudDocs/Desktop/coding/LCKlol/index/management/commands/update.py", line 497, in update_ranking_24_spring_regular
    team1 = self.convert_team_name_24(Ranking_24_spring_regular.objects.get(name=schedule_object.team1_name))
  File "/Library/Frameworks/Python.framework/Versions/3.10/lib/python3.10/site-packages/django/db/models/manager.py", line 85, in manager_method
    return getattr(self.get_queryset(), name)(*args, **kwargs)
  File "/Library/Frameworks/Python.framework/Versions/3.10/lib/python3.10/site-packages/django/db/models/query.py", line 492, in get
    num = len(clone)
  File "/Library/Frameworks/Python.framework/Versions/3.10/lib/python3.10/site-packages/django/db/models/query.py", line 302, in __len__
    self._fetch_all()
  File "/Library/Frameworks/Python.framework/Versions/3.10/lib/python3.10/site-packages/django/db/models/query.py", line 1507, in _fetch_all
    self._result_cache = list(self._iterable_class(self))
  File "/Library/Frameworks/Python.framework/Versions/3.10/lib/python3.10/site-packages/django/db/models/query.py", line 57, in __iter__
    results = compiler.execute_sql(
  File "/Library/Frameworks/Python.framework/Versions/3.10/lib/python3.10/site-packages/django/db/models/sql/compiler.py", line 1361, in execute_sql
    cursor.execute(sql, params)
  File "/Library/Frameworks/Python.framework/Versions/3.10/lib/python3.10/site-packages/django/db/backends/utils.py", line 103, in execute
    return super().execute(sql, params)
  File "/Library/Frameworks/Python.framework/Versions/3.10/lib/python3.10/site-packages/django/db/backends/utils.py", line 67, in execute
    return self._execute_with_wrappers(
  File "/Library/Frameworks/Python.framework/Versions/3.10/lib/python3.10/site-packages/django/db/backends/utils.py", line 80, in _execute_with_wrappers
    return executor(sql, params, many, context)
  File "/Library/Frameworks/Python.framework/Versions/3.10/lib/python3.10/site-packages/django/db/backends/utils.py", line 84, in _execute
    with self.db.wrap_database_errors:
  File "/Library/Frameworks/Python.framework/Versions/3.10/lib/python3.10/site-packages/django/db/utils.py", line 91, in __exit__
    raise dj_exc_value.with_traceback(traceback) from exc_value
  File "/Library/Frameworks/Python.framework/Versions/3.10/lib/python3.10/site-packages/django/db/backends/utils.py", line 89, in _execute
    return self.cursor.execute(sql, params)
  File "/Library/Frameworks/Python.framework/Versions/3.10/lib/python3.10/site-packages/django/db/backends/mysql/base.py", line 75, in execute
    return self.cursor.execute(query, args)
  File "/Library/Frameworks/Python.framework/Versions/3.10/lib/python3.10/site-packages/MySQLdb/cursors.py", line 179, in execute
    res = self._query(mogrified_query)
  File "/Library/Frameworks/Python.framework/Versions/3.10/lib/python3.10/site-packages/MySQLdb/cursors.py", line 330, in _query
    db.query(q)
  File "/Library/Frameworks/Python.framework/Versions/3.10/lib/python3.10/site-packages/MySQLdb/connections.py", line 255, in query
    _mysql.connection.query(self, query)
django.db.utils.OperationalError: (2013, 'Lost connection to MySQL server during query')
-------------------------------------
update schedule complete
update champion complete
Traceback (most recent call last):
  File "/Library/Frameworks/Python.framework/Versions/3.10/lib/python3.10/site-packages/django/db/backends/utils.py", line 89, in _execute
    return self.cursor.execute(sql, params)
  File "/Library/Frameworks/Python.framework/Versions/3.10/lib/python3.10/site-packages/django/db/backends/mysql/base.py", line 75, in execute
    return self.cursor.execute(query, args)
  File "/Library/Frameworks/Python.framework/Versions/3.10/lib/python3.10/site-packages/MySQLdb/cursors.py", line 179, in execute
    res = self._query(mogrified_query)
  File "/Library/Frameworks/Python.framework/Versions/3.10/lib/python3.10/site-packages/MySQLdb/cursors.py", line 330, in _query
    db.query(q)
  File "/Library/Frameworks/Python.framework/Versions/3.10/lib/python3.10/site-packages/MySQLdb/connections.py", line 255, in query
    _mysql.connection.query(self, query)
MySQLdb.OperationalError: (2013, 'Lost connection to MySQL server during query')

The above exception was the direct cause of the following exception:

Traceback (most recent call last):
  File "/Users/kimminseok/Library/Mobile Documents/com~apple~CloudDocs/Desktop/coding/LCKlol/manage.py", line 22, in <module>
    main()
  File "/Users/kimminseok/Library/Mobile Documents/com~apple~CloudDocs/Desktop/coding/LCKlol/manage.py", line 18, in main
    execute_from_command_line(sys.argv)
  File "/Library/Frameworks/Python.framework/Versions/3.10/lib/python3.10/site-packages/django/core/management/__init__.py", line 446, in execute_from_command_line
    utility.execute()
  File "/Library/Frameworks/Python.framework/Versions/3.10/lib/python3.10/site-packages/django/core/management/__init__.py", line 440, in execute
    self.fetch_command(subcommand).run_from_argv(self.argv)
  File "/Library/Frameworks/Python.framework/Versions/3.10/lib/python3.10/site-packages/django/core/management/base.py", line 414, in run_from_argv
    self.execute(*args, **cmd_options)
  File "/Library/Frameworks/Python.framework/Versions/3.10/lib/python3.10/site-packages/django/core/management/base.py", line 460, in execute
    output = self.handle(*args, **options)
  File "/Users/kimminseok/Library/Mobile Documents/com~apple~CloudDocs/Desktop/coding/LCKlol/index/management/commands/update.py", line 527, in handle
    self.update_ranking_24_spring_regular()
  File "/Users/kimminseok/Library/Mobile Documents/com~apple~CloudDocs/Desktop/coding/LCKlol/index/management/commands/update.py", line 498, in update_ranking_24_spring_regular
    team2 = self.convert_team_name_24(Ranking_24_spring_regular.objects.get(name=schedule_object.team2_name))
  File "/Library/Frameworks/Python.framework/Versions/3.10/lib/python3.10/site-packages/django/db/models/manager.py", line 85, in manager_method
    return getattr(self.get_queryset(), name)(*args, **kwargs)
  File "/Library/Frameworks/Python.framework/Versions/3.10/lib/python3.10/site-packages/django/db/models/query.py", line 492, in get
    num = len(clone)
  File "/Library/Frameworks/Python.framework/Versions/3.10/lib/python3.10/site-packages/django/db/models/query.py", line 302, in __len__
    self._fetch_all()
  File "/Library/Frameworks/Python.framework/Versions/3.10/lib/python3.10/site-packages/django/db/models/query.py", line 1507, in _fetch_all
    self._result_cache = list(self._iterable_class(self))
  File "/Library/Frameworks/Python.framework/Versions/3.10/lib/python3.10/site-packages/django/db/models/query.py", line 57, in __iter__
    results = compiler.execute_sql(
  File "/Library/Frameworks/Python.framework/Versions/3.10/lib/python3.10/site-packages/django/db/models/sql/compiler.py", line 1361, in execute_sql
    cursor.execute(sql, params)
  File "/Library/Frameworks/Python.framework/Versions/3.10/lib/python3.10/site-packages/django/db/backends/utils.py", line 103, in execute
    return super().execute(sql, params)
  File "/Library/Frameworks/Python.framework/Versions/3.10/lib/python3.10/site-packages/django/db/backends/utils.py", line 67, in execute
    return self._execute_with_wrappers(
  File "/Library/Frameworks/Python.framework/Versions/3.10/lib/python3.10/site-packages/django/db/backends/utils.py", line 80, in _execute_with_wrappers
    return executor(sql, params, many, context)
  File "/Library/Frameworks/Python.framework/Versions/3.10/lib/python3.10/site-packages/django/db/backends/utils.py", line 84, in _execute
    with self.db.wrap_database_errors:
  File "/Library/Frameworks/Python.framework/Versions/3.10/lib/python3.10/site-packages/django/db/utils.py", line 91, in __exit__
    raise dj_exc_value.with_traceback(traceback) from exc_value
  File "/Library/Frameworks/Python.framework/Versions/3.10/lib/python3.10/site-packages/django/db/backends/utils.py", line 89, in _execute
    return self.cursor.execute(sql, params)
  File "/Library/Frameworks/Python.framework/Versions/3.10/lib/python3.10/site-packages/django/db/backends/mysql/base.py", line 75, in execute
    return self.cursor.execute(query, args)
  File "/Library/Frameworks/Python.framework/Versions/3.10/lib/python3.10/site-packages/MySQLdb/cursors.py", line 179, in execute
    res = self._query(mogrified_query)
  File "/Library/Frameworks/Python.framework/Versions/3.10/lib/python3.10/site-packages/MySQLdb/cursors.py", line 330, in _query
    db.query(q)
  File "/Library/Frameworks/Python.framework/Versions/3.10/lib/python3.10/site-packages/MySQLdb/connections.py", line 255, in query
    _mysql.connection.query(self, query)
django.db.utils.OperationalError: (2013, 'Lost connection to MySQL server during query')
-------------------------------------
Fri Jan 19 20:00:00 JST 2024
update schedule complete
pass: 2024-01-19_1
pass: 2024-01-19_2
update champion complete
update ranking_24_spring complete
-------------------------------------
Fri Jan 19 21:00:00 JST 2024
update schedule complete
update champion complete
Traceback (most recent call last):
  File "/Library/Frameworks/Python.framework/Versions/3.10/lib/python3.10/site-packages/django/db/backends/utils.py", line 89, in _execute
    return self.cursor.execute(sql, params)
  File "/Library/Frameworks/Python.framework/Versions/3.10/lib/python3.10/site-packages/django/db/backends/mysql/base.py", line 75, in execute
    return self.cursor.execute(query, args)
  File "/Library/Frameworks/Python.framework/Versions/3.10/lib/python3.10/site-packages/MySQLdb/cursors.py", line 179, in execute
    res = self._query(mogrified_query)
  File "/Library/Frameworks/Python.framework/Versions/3.10/lib/python3.10/site-packages/MySQLdb/cursors.py", line 330, in _query
    db.query(q)
  File "/Library/Frameworks/Python.framework/Versions/3.10/lib/python3.10/site-packages/MySQLdb/connections.py", line 255, in query
    _mysql.connection.query(self, query)
MySQLdb.OperationalError: (2013, 'Lost connection to MySQL server during query')

The above exception was the direct cause of the following exception:

Traceback (most recent call last):
  File "/Users/kimminseok/Library/Mobile Documents/com~apple~CloudDocs/Desktop/coding/LCKlol/manage.py", line 22, in <module>
    main()
  File "/Users/kimminseok/Library/Mobile Documents/com~apple~CloudDocs/Desktop/coding/LCKlol/manage.py", line 18, in main
    execute_from_command_line(sys.argv)
  File "/Library/Frameworks/Python.framework/Versions/3.10/lib/python3.10/site-packages/django/core/management/__init__.py", line 446, in execute_from_command_line
    utility.execute()
  File "/Library/Frameworks/Python.framework/Versions/3.10/lib/python3.10/site-packages/django/core/management/__init__.py", line 440, in execute
    self.fetch_command(subcommand).run_from_argv(self.argv)
  File "/Library/Frameworks/Python.framework/Versions/3.10/lib/python3.10/site-packages/django/core/management/base.py", line 414, in run_from_argv
    self.execute(*args, **cmd_options)
  File "/Library/Frameworks/Python.framework/Versions/3.10/lib/python3.10/site-packages/django/core/management/base.py", line 460, in execute
    output = self.handle(*args, **options)
  File "/Users/kimminseok/Library/Mobile Documents/com~apple~CloudDocs/Desktop/coding/LCKlol/index/management/commands/update.py", line 527, in handle
    self.update_ranking_24_spring_regular()
  File "/Users/kimminseok/Library/Mobile Documents/com~apple~CloudDocs/Desktop/coding/LCKlol/index/management/commands/update.py", line 492, in update_ranking_24_spring_regular
    self.reset_ranking_24_spring_regular()
  File "/Users/kimminseok/Library/Mobile Documents/com~apple~CloudDocs/Desktop/coding/LCKlol/index/management/commands/update.py", line 483, in reset_ranking_24_spring_regular
    team_object = Ranking_24_spring_regular.objects.get(tricode=team)
  File "/Library/Frameworks/Python.framework/Versions/3.10/lib/python3.10/site-packages/django/db/models/manager.py", line 85, in manager_method
    return getattr(self.get_queryset(), name)(*args, **kwargs)
  File "/Library/Frameworks/Python.framework/Versions/3.10/lib/python3.10/site-packages/django/db/models/query.py", line 492, in get
    num = len(clone)
  File "/Library/Frameworks/Python.framework/Versions/3.10/lib/python3.10/site-packages/django/db/models/query.py", line 302, in __len__
    self._fetch_all()
  File "/Library/Frameworks/Python.framework/Versions/3.10/lib/python3.10/site-packages/django/db/models/query.py", line 1507, in _fetch_all
    self._result_cache = list(self._iterable_class(self))
  File "/Library/Frameworks/Python.framework/Versions/3.10/lib/python3.10/site-packages/django/db/models/query.py", line 57, in __iter__
    results = compiler.execute_sql(
  File "/Library/Frameworks/Python.framework/Versions/3.10/lib/python3.10/site-packages/django/db/models/sql/compiler.py", line 1361, in execute_sql
    cursor.execute(sql, params)
  File "/Library/Frameworks/Python.framework/Versions/3.10/lib/python3.10/site-packages/django/db/backends/utils.py", line 103, in execute
    return super().execute(sql, params)
  File "/Library/Frameworks/Python.framework/Versions/3.10/lib/python3.10/site-packages/django/db/backends/utils.py", line 67, in execute
    return self._execute_with_wrappers(
  File "/Library/Frameworks/Python.framework/Versions/3.10/lib/python3.10/site-packages/django/db/backends/utils.py", line 80, in _execute_with_wrappers
    return executor(sql, params, many, context)
  File "/Library/Frameworks/Python.framework/Versions/3.10/lib/python3.10/site-packages/django/db/backends/utils.py", line 84, in _execute
    with self.db.wrap_database_errors:
  File "/Library/Frameworks/Python.framework/Versions/3.10/lib/python3.10/site-packages/django/db/utils.py", line 91, in __exit__
    raise dj_exc_value.with_traceback(traceback) from exc_value
  File "/Library/Frameworks/Python.framework/Versions/3.10/lib/python3.10/site-packages/django/db/backends/utils.py", line 89, in _execute
    return self.cursor.execute(sql, params)
  File "/Library/Frameworks/Python.framework/Versions/3.10/lib/python3.10/site-packages/django/db/backends/mysql/base.py", line 75, in execute
    return self.cursor.execute(query, args)
  File "/Library/Frameworks/Python.framework/Versions/3.10/lib/python3.10/site-packages/MySQLdb/cursors.py", line 179, in execute
    res = self._query(mogrified_query)
  File "/Library/Frameworks/Python.framework/Versions/3.10/lib/python3.10/site-packages/MySQLdb/cursors.py", line 330, in _query
    db.query(q)
  File "/Library/Frameworks/Python.framework/Versions/3.10/lib/python3.10/site-packages/MySQLdb/connections.py", line 255, in query
    _mysql.connection.query(self, query)
django.db.utils.OperationalError: (2013, 'Lost connection to MySQL server during query')
-------------------------------------
Fri Jan 19 22:00:00 JST 2024
update schedule complete
pass: 2024-01-19_3
update champion complete
update ranking_24_spring complete
-------------------------------------
Fri Jan 19 23:00:00 JST 2024
update schedule complete
pass: 2024-01-19_4
update champion complete
update ranking_24_spring complete
-------------------------------------
Sat Jan 20 00:00:00 JST 2024
update schedule complete
update champion complete
update ranking_24_spring complete
-------------------------------------
Sat Jan 20 01:00:00 JST 2024
update schedule complete
update champion complete
update ranking_24_spring complete
-------------------------------------
Sat Jan 20 04:00:01 JST 2024
update schedule complete
update champion complete
update ranking_24_spring complete
-------------------------------------
Sat Jan 20 05:00:00 JST 2024
update schedule complete
update champion complete
update ranking_24_spring complete
-------------------------------------
Sat Jan 20 09:00:00 JST 2024
update schedule complete
update champion complete
update ranking_24_spring complete
-------------------------------------
Sat Jan 20 12:00:01 JST 2024
update schedule complete
update champion complete
update ranking_24_spring complete
-------------------------------------
Sat Jan 20 13:00:00 JST 2024
update schedule complete
update champion complete
update ranking_24_spring complete
-------------------------------------
Sat Jan 20 14:00:00 JST 2024
update schedule complete
update champion complete
update ranking_24_spring complete
-------------------------------------
Sat Jan 20 15:00:00 JST 2024
update schedule complete
update champion complete
update ranking_24_spring complete
-------------------------------------
Sat Jan 20 16:01:13 JST 2024
update schedule complete
Traceback (most recent call last):
  File "/Users/kimminseok/Library/Mobile Documents/com~apple~CloudDocs/Desktop/coding/LCKlol/manage.py", line 22, in <module>
    main()
  File "/Users/kimminseok/Library/Mobile Documents/com~apple~CloudDocs/Desktop/coding/LCKlol/manage.py", line 18, in main
    execute_from_command_line(sys.argv)
  File "/Library/Frameworks/Python.framework/Versions/3.10/lib/python3.10/site-packages/django/core/management/__init__.py", line 446, in execute_from_command_line
    utility.execute()
  File "/Library/Frameworks/Python.framework/Versions/3.10/lib/python3.10/site-packages/django/core/management/__init__.py", line 440, in execute
    self.fetch_command(subcommand).run_from_argv(self.argv)
  File "/Library/Frameworks/Python.framework/Versions/3.10/lib/python3.10/site-packages/django/core/management/base.py", line 414, in run_from_argv
    self.execute(*args, **cmd_options)
  File "/Library/Frameworks/Python.framework/Versions/3.10/lib/python3.10/site-packages/django/core/management/base.py", line 460, in execute
    output = self.handle(*args, **options)
  File "/Users/kimminseok/Library/Mobile Documents/com~apple~CloudDocs/Desktop/coding/LCKlol/index/management/commands/update.py", line 525, in handle
    self.update_champion()
  File "/Users/kimminseok/Library/Mobile Documents/com~apple~CloudDocs/Desktop/coding/LCKlol/index/management/commands/update.py", line 365, in update_champion
    web_source = driver.page_source
  File "/Library/Frameworks/Python.framework/Versions/3.10/lib/python3.10/site-packages/selenium/webdriver/remote/webdriver.py", line 445, in page_source
    return self.execute(Command.GET_PAGE_SOURCE)["value"]
  File "/Library/Frameworks/Python.framework/Versions/3.10/lib/python3.10/site-packages/selenium/webdriver/remote/webdriver.py", line 344, in execute
    self.error_handler.check_response(response)
  File "/Library/Frameworks/Python.framework/Versions/3.10/lib/python3.10/site-packages/selenium/webdriver/remote/errorhandler.py", line 229, in check_response
    raise exception_class(message, screen, stacktrace)
selenium.common.exceptions.WebDriverException: Message: disconnected: not connected to DevTools
  (failed to check if window was closed: disconnected: not connected to DevTools)
  (Session info: chrome-headless-shell=120.0.6099.234)
Stacktrace:
0   chromedriver                        0x00000001047e84dc chromedriver + 4162780
1   chromedriver                        0x00000001047e0664 chromedriver + 4130404
2   chromedriver                        0x0000000104437bc0 chromedriver + 293824
3   chromedriver                        0x000000010441f0b0 chromedriver + 192688
4   chromedriver                        0x000000010441efd8 chromedriver + 192472
5   chromedriver                        0x00000001044bd2b0 chromedriver + 840368
6   chromedriver                        0x00000001044716bc chromedriver + 530108
7   chromedriver                        0x0000000104472930 chromedriver + 534832
8   chromedriver                        0x00000001047ade08 chromedriver + 3923464
9   chromedriver                        0x00000001047b23dc chromedriver + 3941340
10  chromedriver                        0x0000000104796038 chromedriver + 3825720
11  chromedriver                        0x00000001047b2f3c chromedriver + 3944252
12  chromedriver                        0x00000001047886f4 chromedriver + 3770100
13  chromedriver                        0x00000001047cf980 chromedriver + 4061568
14  chromedriver                        0x00000001047cfaf8 chromedriver + 4061944
15  chromedriver                        0x00000001047e02e4 chromedriver + 4129508
16  libsystem_pthread.dylib             0x0000000183ba2034 _pthread_start + 136
17  libsystem_pthread.dylib             0x0000000183b9ce3c thread_start + 8

-------------------------------------
Sat Jan 20 18:00:00 JST 2024
update schedule complete
pass: 2024-01-20_1
pass: 2024-01-20_2
update champion complete
update ranking_24_spring complete
-------------------------------------
Sat Jan 20 19:00:00 JST 2024
update schedule complete
update champion complete
update ranking_24_spring complete
-------------------------------------
Sat Jan 20 20:00:00 JST 2024
update schedule complete
pass: 2024-01-20_3
pass: 2024-01-20_4
update champion complete
update ranking_24_spring complete
-------------------------------------
Sat Jan 20 21:00:00 JST 2024
update schedule complete
update champion complete
update ranking_24_spring complete
-------------------------------------
Sat Jan 20 22:00:00 JST 2024
update schedule complete
update champion complete
update ranking_24_spring complete
-------------------------------------
Sat Jan 20 23:00:00 JST 2024
update schedule complete
update champion complete
update ranking_24_spring complete
-------------------------------------
Sun Jan 21 00:00:00 JST 2024
update schedule complete
update champion complete
update ranking_24_spring complete
-------------------------------------
Sun Jan 21 01:00:00 JST 2024
update schedule complete
update champion complete
update ranking_24_spring complete
-------------------------------------
Sun Jan 21 02:00:00 JST 2024
update schedule complete
update champion complete
update ranking_24_spring complete
-------------------------------------
Sun Jan 21 03:00:00 JST 2024
update schedule complete
update champion complete
update ranking_24_spring complete
-------------------------------------
Sun Jan 21 04:00:00 JST 2024
update schedule complete
update champion complete
update ranking_24_spring complete
-------------------------------------
Sun Jan 21 05:00:01 JST 2024
update schedule complete
update champion complete
update ranking_24_spring complete
-------------------------------------
Sun Jan 21 06:00:00 JST 2024
update schedule complete
update champion complete
update ranking_24_spring complete
-------------------------------------
Sun Jan 21 07:00:00 JST 2024
update schedule complete
update champion complete
update ranking_24_spring complete
-------------------------------------
Sun Jan 21 08:00:01 JST 2024
update schedule complete
update champion complete
update ranking_24_spring complete
-------------------------------------
Sun Jan 21 09:00:00 JST 2024
update schedule complete
update champion complete
update ranking_24_spring complete
-------------------------------------
Sun Jan 21 10:00:00 JST 2024
update schedule complete
update champion complete
update ranking_24_spring complete
-------------------------------------
Sun Jan 21 11:00:00 JST 2024
update schedule complete
update champion complete
update ranking_24_spring complete
-------------------------------------
Sun Jan 21 12:00:00 JST 2024
update schedule complete
update champion complete
update ranking_24_spring complete
-------------------------------------
Sun Jan 21 13:00:00 JST 2024
update schedule complete
update champion complete
update ranking_24_spring complete
-------------------------------------
Sun Jan 21 14:00:00 JST 2024
update schedule complete
update champion complete
update ranking_24_spring complete
-------------------------------------
Sun Jan 21 15:00:00 JST 2024
update schedule complete
update champion complete
update ranking_24_spring complete
-------------------------------------
Sun Jan 21 16:00:00 JST 2024
update schedule complete
update champion complete
update ranking_24_spring complete
-------------------------------------
Sun Jan 21 17:00:00 JST 2024
update schedule complete
pass: 2024-01-21_1
update champion complete
update ranking_24_spring complete
-------------------------------------
Sun Jan 21 18:00:01 JST 2024
update schedule complete
pass: 2024-01-21_2
update champion complete
update ranking_24_spring complete
-------------------------------------
Sun Jan 21 19:00:00 JST 2024
update schedule complete
update champion complete
update ranking_24_spring complete
-------------------------------------
Sun Jan 21 20:00:00 JST 2024
update schedule complete
update champion complete
update ranking_24_spring complete
-------------------------------------
Sun Jan 21 21:00:00 JST 2024
update schedule complete
update champion complete
update ranking_24_spring complete
-------------------------------------
Sun Jan 21 22:00:00 JST 2024
update schedule complete
update champion complete
update ranking_24_spring complete
-------------------------------------
Sun Jan 21 23:00:00 JST 2024
update schedule complete
update champion complete
update ranking_24_spring complete
-------------------------------------
Mon Jan 22 00:00:00 JST 2024
update schedule complete
pass: 2024-01-21_3
pass: 2024-01-21_4
pass: 2024-01-21_5
update champion complete
update ranking_24_spring complete
-------------------------------------
Mon Jan 22 01:00:00 JST 2024
update schedule complete
update champion complete
update ranking_24_spring complete
-------------------------------------
Mon Jan 22 08:00:00 JST 2024
update schedule complete
update champion complete
update ranking_24_spring complete
-------------------------------------
Mon Jan 22 16:00:00 JST 2024
Traceback (most recent call last):
  File "/Library/Frameworks/Python.framework/Versions/3.10/lib/python3.10/site-packages/selenium/webdriver/common/driver_finder.py", line 38, in get_path
    path = SeleniumManager().driver_location(options) if path is None else path
  File "/Library/Frameworks/Python.framework/Versions/3.10/lib/python3.10/site-packages/selenium/webdriver/common/selenium_manager.py", line 95, in driver_location
    output = self.run(args)
  File "/Library/Frameworks/Python.framework/Versions/3.10/lib/python3.10/site-packages/selenium/webdriver/common/selenium_manager.py", line 141, in run
    raise WebDriverException(f"Unsuccessful command executed: {command}.\n{result}{stderr}")
selenium.common.exceptions.WebDriverException: Message: Unsuccessful command executed: /Library/Frameworks/Python.framework/Versions/3.10/lib/python3.10/site-packages/selenium/webdriver/common/macos/selenium-manager --browser chrome --output json.
{'code': 65, 'message': 'error sending request for url (https://googlechromelabs.github.io/chrome-for-testing/known-good-versions-with-downloads.json): error trying to connect: dns error: failed to lookup address information: nodename nor servname provided, or not known', 'driver_path': '', 'browser_path': ''}


The above exception was the direct cause of the following exception:

Traceback (most recent call last):
  File "/Users/kimminseok/Library/Mobile Documents/com~apple~CloudDocs/Desktop/coding/LCKlol/manage.py", line 22, in <module>
    main()
  File "/Users/kimminseok/Library/Mobile Documents/com~apple~CloudDocs/Desktop/coding/LCKlol/manage.py", line 18, in main
    execute_from_command_line(sys.argv)
  File "/Library/Frameworks/Python.framework/Versions/3.10/lib/python3.10/site-packages/django/core/management/__init__.py", line 446, in execute_from_command_line
    utility.execute()
  File "/Library/Frameworks/Python.framework/Versions/3.10/lib/python3.10/site-packages/django/core/management/__init__.py", line 440, in execute
    self.fetch_command(subcommand).run_from_argv(self.argv)
  File "/Library/Frameworks/Python.framework/Versions/3.10/lib/python3.10/site-packages/django/core/management/base.py", line 414, in run_from_argv
    self.execute(*args, **cmd_options)
  File "/Library/Frameworks/Python.framework/Versions/3.10/lib/python3.10/site-packages/django/core/management/base.py", line 460, in execute
    output = self.handle(*args, **options)
  File "/Users/kimminseok/Library/Mobile Documents/com~apple~CloudDocs/Desktop/coding/LCKlol/index/management/commands/update.py", line 523, in handle
    self.update_schedule()
  File "/Users/kimminseok/Library/Mobile Documents/com~apple~CloudDocs/Desktop/coding/LCKlol/index/management/commands/update.py", line 26, in update_schedule
    driver = webdriver.Chrome(option)
  File "/Library/Frameworks/Python.framework/Versions/3.10/lib/python3.10/site-packages/selenium/webdriver/chrome/webdriver.py", line 45, in __init__
    super().__init__(
  File "/Library/Frameworks/Python.framework/Versions/3.10/lib/python3.10/site-packages/selenium/webdriver/chromium/webdriver.py", line 51, in __init__
    self.service.path = DriverFinder.get_path(self.service, options)
  File "/Library/Frameworks/Python.framework/Versions/3.10/lib/python3.10/site-packages/selenium/webdriver/common/driver_finder.py", line 41, in get_path
    raise NoSuchDriverException(msg) from err
selenium.common.exceptions.NoSuchDriverException: Message: Unable to obtain driver for chrome using Selenium Manager.; For documentation on this error, please visit: https://www.selenium.dev/documentation/webdriver/troubleshooting/errors/driver_location

-------------------------------------
Mon Jan 22 17:00:44 JST 2024
Traceback (most recent call last):
  File "/Library/Frameworks/Python.framework/Versions/3.10/lib/python3.10/site-packages/selenium/webdriver/common/driver_finder.py", line 38, in get_path
    path = SeleniumManager().driver_location(options) if path is None else path
  File "/Library/Frameworks/Python.framework/Versions/3.10/lib/python3.10/site-packages/selenium/webdriver/common/selenium_manager.py", line 95, in driver_location
    output = self.run(args)
  File "/Library/Frameworks/Python.framework/Versions/3.10/lib/python3.10/site-packages/selenium/webdriver/common/selenium_manager.py", line 141, in run
    raise WebDriverException(f"Unsuccessful command executed: {command}.\n{result}{stderr}")
selenium.common.exceptions.WebDriverException: Message: Unsuccessful command executed: /Library/Frameworks/Python.framework/Versions/3.10/lib/python3.10/site-packages/selenium/webdriver/common/macos/selenium-manager --browser chrome --output json.
{'code': 65, 'message': 'error sending request for url (https://googlechromelabs.github.io/chrome-for-testing/known-good-versions-with-downloads.json): error trying to connect: dns error: failed to lookup address information: nodename nor servname provided, or not known', 'driver_path': '', 'browser_path': ''}


The above exception was the direct cause of the following exception:

Traceback (most recent call last):
  File "/Users/kimminseok/Library/Mobile Documents/com~apple~CloudDocs/Desktop/coding/LCKlol/manage.py", line 22, in <module>
    main()
  File "/Users/kimminseok/Library/Mobile Documents/com~apple~CloudDocs/Desktop/coding/LCKlol/manage.py", line 18, in main
    execute_from_command_line(sys.argv)
  File "/Library/Frameworks/Python.framework/Versions/3.10/lib/python3.10/site-packages/django/core/management/__init__.py", line 446, in execute_from_command_line
    utility.execute()
  File "/Library/Frameworks/Python.framework/Versions/3.10/lib/python3.10/site-packages/django/core/management/__init__.py", line 440, in execute
    self.fetch_command(subcommand).run_from_argv(self.argv)
  File "/Library/Frameworks/Python.framework/Versions/3.10/lib/python3.10/site-packages/django/core/management/base.py", line 414, in run_from_argv
    self.execute(*args, **cmd_options)
  File "/Library/Frameworks/Python.framework/Versions/3.10/lib/python3.10/site-packages/django/core/management/base.py", line 460, in execute
    output = self.handle(*args, **options)
  File "/Users/kimminseok/Library/Mobile Documents/com~apple~CloudDocs/Desktop/coding/LCKlol/index/management/commands/update.py", line 523, in handle
    self.update_schedule()
  File "/Users/kimminseok/Library/Mobile Documents/com~apple~CloudDocs/Desktop/coding/LCKlol/index/management/commands/update.py", line 26, in update_schedule
    driver = webdriver.Chrome(option)
  File "/Library/Frameworks/Python.framework/Versions/3.10/lib/python3.10/site-packages/selenium/webdriver/chrome/webdriver.py", line 45, in __init__
    super().__init__(
  File "/Library/Frameworks/Python.framework/Versions/3.10/lib/python3.10/site-packages/selenium/webdriver/chromium/webdriver.py", line 51, in __init__
    self.service.path = DriverFinder.get_path(self.service, options)
  File "/Library/Frameworks/Python.framework/Versions/3.10/lib/python3.10/site-packages/selenium/webdriver/common/driver_finder.py", line 41, in get_path
    raise NoSuchDriverException(msg) from err
selenium.common.exceptions.NoSuchDriverException: Message: Unable to obtain driver for chrome using Selenium Manager.; For documentation on this error, please visit: https://www.selenium.dev/documentation/webdriver/troubleshooting/errors/driver_location

-------------------------------------
